[32m2022-10-28 09:39:48 +0000[0m - dagster - [34mDEBUG[0m - generate_trajectories - efaee287-373a-4b06-be8e-f8ce69dddfaf - 3764 - collect_data - LOGS_CAPTURED - Started capturing logs for step: collect_data.
[32m2022-10-28 09:39:48 +0000[0m - dagster - [34mDEBUG[0m - generate_trajectories - efaee287-373a-4b06-be8e-f8ce69dddfaf - 3764 - collect_data - STEP_START - Started execution of step "collect_data".
[32m2022-10-28 09:39:48 +0000[0m - dagster - [34mDEBUG[0m - generate_trajectories - efaee287-373a-4b06-be8e-f8ce69dddfaf - 3764 - collect_data - LOADED_INPUT - Loaded input "interval" using input manager "io_manager", from output "result" of step "get_interval"
[32m2022-10-28 09:39:48 +0000[0m - dagster - [34mDEBUG[0m - generate_trajectories - efaee287-373a-4b06-be8e-f8ce69dddfaf - 3764 - collect_data - STEP_INPUT - Got input "interval" of type "Tuple[datetime,datetime]". (Type check passed).
nats: encountered error
Traceback (most recent call last):
  File "/usr/local/lib/python3.10/site-packages/nats/aio/client.py", line 1301, in _select_next_server
    await self._transport.connect(
  File "/usr/local/lib/python3.10/site-packages/nats/aio/transport.py", line 118, in connect
    r, w = await asyncio.wait_for(
  File "/usr/local/lib/python3.10/asyncio/tasks.py", line 445, in wait_for
    return fut.result()
  File "/usr/local/lib/python3.10/asyncio/streams.py", line 48, in open_connection
    transport, _ = await loop.create_connection(
  File "/usr/local/lib/python3.10/asyncio/base_events.py", line 1075, in create_connection
    raise OSError('Multiple exceptions: {}'.format(
OSError: Multiple exceptions: [Errno 111] Connect call failed ('127.0.0.1', 4222), [Errno 99] Cannot assign requested address
nats: encountered error
Traceback (most recent call last):
  File "/usr/local/lib/python3.10/site-packages/nats/aio/client.py", line 1301, in _select_next_server
    await self._transport.connect(
  File "/usr/local/lib/python3.10/site-packages/nats/aio/transport.py", line 118, in connect
    r, w = await asyncio.wait_for(
  File "/usr/local/lib/python3.10/asyncio/tasks.py", line 445, in wait_for
    return fut.result()
  File "/usr/local/lib/python3.10/asyncio/streams.py", line 48, in open_connection
    transport, _ = await loop.create_connection(
  File "/usr/local/lib/python3.10/asyncio/base_events.py", line 1075, in create_connection
    raise OSError('Multiple exceptions: {}'.format(
OSError: Multiple exceptions: [Errno 111] Connect call failed ('127.0.0.1', 4222), [Errno 99] Cannot assign requested address
nats: encountered error
Traceback (most recent call last):
  File "/usr/local/lib/python3.10/site-packages/nats/aio/client.py", line 1301, in _select_next_server
    await self._transport.connect(
  File "/usr/local/lib/python3.10/site-packages/nats/aio/transport.py", line 118, in connect
    r, w = await asyncio.wait_for(
  File "/usr/local/lib/python3.10/asyncio/tasks.py", line 445, in wait_for
    return fut.result()
  File "/usr/local/lib/python3.10/asyncio/streams.py", line 48, in open_connection
    transport, _ = await loop.create_connection(
  File "/usr/local/lib/python3.10/asyncio/base_events.py", line 1075, in create_connection
    raise OSError('Multiple exceptions: {}'.format(
OSError: Multiple exceptions: [Errno 111] Connect call failed ('127.0.0.1', 4222), [Errno 99] Cannot assign requested address
nats: encountered error
Traceback (most recent call last):
  File "/usr/local/lib/python3.10/site-packages/nats/aio/client.py", line 1301, in _select_next_server
    await self._transport.connect(
  File "/usr/local/lib/python3.10/site-packages/nats/aio/transport.py", line 118, in connect
    r, w = await asyncio.wait_for(
  File "/usr/local/lib/python3.10/asyncio/tasks.py", line 445, in wait_for
    return fut.result()
  File "/usr/local/lib/python3.10/asyncio/streams.py", line 48, in open_connection
    transport, _ = await loop.create_connection(
  File "/usr/local/lib/python3.10/asyncio/base_events.py", line 1075, in create_connection
    raise OSError('Multiple exceptions: {}'.format(
OSError: Multiple exceptions: [Errno 111] Connect call failed ('127.0.0.1', 4222), [Errno 99] Cannot assign requested address
[32m2022-10-28 09:39:56 +0000[0m - dagster - [34mERROR[0m - [31mgenerate_trajectories - efaee287-373a-4b06-be8e-f8ce69dddfaf - 3764 - collect_data - STEP_FAILURE - Execution of step "collect_data" failed.

dagster._core.errors.DagsterExecutionStepExecutionError: Error occurred while executing op "collect_data"::

TypeError: 'NoneType' object is not subscriptable

Stack Trace:
  File "/usr/local/lib/python3.10/site-packages/dagster/_core/execution/plan/utils.py", line 47, in solid_execution_error_boundary
    yield
  File "/usr/local/lib/python3.10/site-packages/dagster/_utils/__init__.py", line 430, in iterate_with_context
    next_output = next(iterator)
  File "/usr/local/lib/python3.10/site-packages/dagster/_core/execution/plan/compute.py", line 109, in gen_from_async_gen
    yield loop.run_until_complete(async_gen.__anext__())
  File "/usr/local/lib/python3.10/asyncio/base_events.py", line 649, in run_until_complete
    return future.result()
  File "/usr/local/lib/python3.10/site-packages/dagster/_core/execution/plan/compute_generator.py", line 68, in _coerce_async_solid_to_async_gen
    result = await awaitable
  File "/workspaces/pipeline-environment/dagster_ais/dagster_ais/ops/trajectory_ops.py", line 22, in collect_data
    psub = await js.subscribe("ais", durable="fff")
  File "/usr/local/lib/python3.10/site-packages/nats/js/client.py", line 202, in subscribe
    stream = await self._jsm.find_stream_name_by_subject(subject)
  File "/usr/local/lib/python3.10/site-packages/nats/js/manager.py", line 65, in find_stream_name_by_subject
    return info['streams'][0]
[0m
