[32m2022-10-23 14:08:22 +0000[0m - dagster - [34mDEBUG[0m - dump_to_s3 - 9ee9ac5e-4e80-4bf1-ba0b-398b349ec0ac - 11175 - collect_messages - LOGS_CAPTURED - Started capturing logs for step: collect_messages.
[32m2022-10-23 14:08:22 +0000[0m - dagster - [34mDEBUG[0m - dump_to_s3 - 9ee9ac5e-4e80-4bf1-ba0b-398b349ec0ac - 11175 - collect_messages - STEP_START - Started execution of step "collect_messages".
[32m2022-10-23 14:08:22 +0000[0m - dagster - [34mDEBUG[0m - dump_to_s3 - 9ee9ac5e-4e80-4bf1-ba0b-398b349ec0ac - 11175 - collect_messages - LOADED_INPUT - Loaded input "create_dump_file" using input manager "io_manager", from output "result" of step "get_interval"
[32m2022-10-23 14:08:22 +0000[0m - dagster - [34mDEBUG[0m - dump_to_s3 - 9ee9ac5e-4e80-4bf1-ba0b-398b349ec0ac - 11175 - collect_messages - STEP_INPUT - Got input "create_dump_file" of type "Tuple[datetime,datetime]". (Type check passed).
[32m2022-10-23 14:08:42 +0000[0m - dagster - [34mERROR[0m - [31mdump_to_s3 - 9ee9ac5e-4e80-4bf1-ba0b-398b349ec0ac - 11175 - collect_messages - STEP_FAILURE - Execution of step "collect_messages" failed.

dagster._core.errors.DagsterExecutionStepExecutionError: Error occurred while executing op "collect_messages"::

nats.errors.TimeoutError: nats: timeout

Stack Trace:
  File "/usr/local/lib/python3.10/site-packages/dagster/_core/execution/plan/utils.py", line 47, in solid_execution_error_boundary
    yield
  File "/usr/local/lib/python3.10/site-packages/dagster/_utils/__init__.py", line 430, in iterate_with_context
    next_output = next(iterator)
  File "/usr/local/lib/python3.10/site-packages/dagster/_core/execution/plan/compute.py", line 109, in gen_from_async_gen
    yield loop.run_until_complete(async_gen.__anext__())
  File "/usr/local/lib/python3.10/asyncio/base_events.py", line 649, in run_until_complete
    return future.result()
  File "/usr/local/lib/python3.10/site-packages/dagster/_core/execution/plan/compute_generator.py", line 68, in _coerce_async_solid_to_async_gen
    result = await awaitable
  File "/workspaces/pipeline-environment/dagster_ais/dagster_ais/ops/dump_to_s3_ops.py", line 35, in collect_messages
    messages_df = await get_messages(start_time, end_time, psub)
  File "/workspaces/pipeline-environment/dagster_ais/dagster_ais/ops/dump_to_s3_ops.py", line 79, in get_messages
    msg = await psub.next_msg(20)
  File "/usr/local/lib/python3.10/site-packages/nats/aio/subscription.py", line 173, in next_msg
    raise errors.TimeoutError
[0m
