[32m2022-12-20 15:57:24 +0000[0m - dagster - [34mDEBUG[0m - generate_trajectories - 40b5acdc-517d-43ea-80d5-e1eb2a3e972e - 28471 - LOGS_CAPTURED - Started capturing logs in process (pid: 28471).
[32m2022-12-20 15:57:24 +0000[0m - dagster - [34mDEBUG[0m - generate_trajectories - 40b5acdc-517d-43ea-80d5-e1eb2a3e972e - 28471 - collect_data - STEP_START - Started execution of step "collect_data".
[32m2022-12-20 15:57:24 +0000[0m - dagster - [34mDEBUG[0m - generate_trajectories - 40b5acdc-517d-43ea-80d5-e1eb2a3e972e - collect_data - Loading file from: /workspaces/pipeline-environment/dagster_pipelines/storage/40b5acdc-517d-43ea-80d5-e1eb2a3e972e/get_interval/result
[32m2022-12-20 15:57:24 +0000[0m - dagster - [34mDEBUG[0m - generate_trajectories - 40b5acdc-517d-43ea-80d5-e1eb2a3e972e - 28471 - collect_data - LOADED_INPUT - Loaded input "interval" using input manager "io_manager", from output "result" of step "get_interval"
[32m2022-12-20 15:57:24 +0000[0m - dagster - [34mDEBUG[0m - generate_trajectories - 40b5acdc-517d-43ea-80d5-e1eb2a3e972e - 28471 - collect_data - STEP_INPUT - Got input "interval" of type "Tuple[datetime,datetime]". (Type check passed).
[32m2022-12-20 15:57:44 +0000[0m - dagster - [34mERROR[0m - [31mgenerate_trajectories - 40b5acdc-517d-43ea-80d5-e1eb2a3e972e - 28471 - collect_data - STEP_FAILURE - Execution of step "collect_data" failed.

dagster._core.errors.DagsterExecutionStepExecutionError: Error occurred while executing op "collect_data"::

nats.errors.TimeoutError: nats: timeout

Stack Trace:
  File "/usr/local/lib/python3.10/site-packages/dagster/_core/execution/plan/utils.py", line 56, in op_execution_error_boundary
    yield
  File "/usr/local/lib/python3.10/site-packages/dagster/_utils/__init__.py", line 458, in iterate_with_context
    next_output = next(iterator)
  File "/usr/local/lib/python3.10/site-packages/dagster/_core/execution/plan/compute.py", line 112, in gen_from_async_gen
    yield loop.run_until_complete(async_gen.__anext__())
  File "/usr/local/lib/python3.10/asyncio/base_events.py", line 649, in run_until_complete
    return future.result()
  File "/usr/local/lib/python3.10/site-packages/dagster/_core/execution/plan/compute_generator.py", line 69, in _coerce_async_solid_to_async_gen
    result = await awaitable
  File "/workspaces/pipeline-environment/dagster_pipelines/dagster_pipelines/ops/trajectory_ops.py", line 25, in collect_data
    df_list = await get_messages(psub, end_time, start_time)
  File "/workspaces/pipeline-environment/dagster_pipelines/dagster_pipelines/ops/trajectory_ops.py", line 155, in get_messages
    msg = await psub.next_msg(20)
  File "/usr/local/lib/python3.10/site-packages/nats/aio/subscription.py", line 173, in next_msg
    raise errors.TimeoutError
[0m
