[32m2022-10-05 15:59:54 +0000[0m - dagster - [34mDEBUG[0m - dump_to_s3 - 4704635f-cbe5-4de7-9b05-4cf3b0036a5a - 27014 - collect_data - LOGS_CAPTURED - Started capturing logs for step: collect_data.
[32m2022-10-05 15:59:54 +0000[0m - dagster - [34mDEBUG[0m - dump_to_s3 - 4704635f-cbe5-4de7-9b05-4cf3b0036a5a - 27014 - collect_data - STEP_START - Started execution of step "collect_data".
[32m2022-10-05 15:59:54 +0000[0m - dagster - [34mDEBUG[0m - dump_to_s3 - 4704635f-cbe5-4de7-9b05-4cf3b0036a5a - 27014 - collect_data - LOADED_INPUT - Loaded input "create_dump_file" using input manager "io_manager", from output "result" of step "create_dump_file"
[32m2022-10-05 15:59:54 +0000[0m - dagster - [34mDEBUG[0m - dump_to_s3 - 4704635f-cbe5-4de7-9b05-4cf3b0036a5a - 27014 - collect_data - STEP_INPUT - Got input "create_dump_file" of type "Any". (Type check passed).
nats: encountered error
Traceback (most recent call last):
  File "/usr/local/lib/python3.10/site-packages/nats/aio/client.py", line 1301, in _select_next_server
    await self._transport.connect(
  File "/usr/local/lib/python3.10/site-packages/nats/aio/transport.py", line 118, in connect
    r, w = await asyncio.wait_for(
  File "/usr/local/lib/python3.10/asyncio/tasks.py", line 445, in wait_for
    return fut.result()
  File "/usr/local/lib/python3.10/asyncio/streams.py", line 47, in open_connection
    transport, _ = await loop.create_connection(
  File "/usr/local/lib/python3.10/asyncio/base_events.py", line 1025, in create_connection
    infos = await self._ensure_resolved(
  File "/usr/local/lib/python3.10/asyncio/base_events.py", line 1404, in _ensure_resolved
    return await loop.getaddrinfo(host, port, family=family, type=type,
  File "/usr/local/lib/python3.10/asyncio/base_events.py", line 860, in getaddrinfo
    return await self.run_in_executor(
  File "/usr/local/lib/python3.10/concurrent/futures/thread.py", line 58, in run
    result = self.fn(*self.args, **self.kwargs)
  File "/usr/local/lib/python3.10/socket.py", line 955, in getaddrinfo
    for res in _socket.getaddrinfo(host, port, family, type, proto, flags):
socket.gaierror: [Errno -2] Name or service not known
nats: encountered error
Traceback (most recent call last):
  File "/usr/local/lib/python3.10/site-packages/nats/aio/client.py", line 1301, in _select_next_server
    await self._transport.connect(
  File "/usr/local/lib/python3.10/site-packages/nats/aio/transport.py", line 118, in connect
    r, w = await asyncio.wait_for(
  File "/usr/local/lib/python3.10/asyncio/tasks.py", line 445, in wait_for
    return fut.result()
  File "/usr/local/lib/python3.10/asyncio/streams.py", line 47, in open_connection
    transport, _ = await loop.create_connection(
  File "/usr/local/lib/python3.10/asyncio/base_events.py", line 1025, in create_connection
    infos = await self._ensure_resolved(
  File "/usr/local/lib/python3.10/asyncio/base_events.py", line 1404, in _ensure_resolved
    return await loop.getaddrinfo(host, port, family=family, type=type,
  File "/usr/local/lib/python3.10/asyncio/base_events.py", line 860, in getaddrinfo
    return await self.run_in_executor(
  File "/usr/local/lib/python3.10/concurrent/futures/thread.py", line 58, in run
    result = self.fn(*self.args, **self.kwargs)
  File "/usr/local/lib/python3.10/socket.py", line 955, in getaddrinfo
    for res in _socket.getaddrinfo(host, port, family, type, proto, flags):
socket.gaierror: [Errno -2] Name or service not known
nats: encountered error
Traceback (most recent call last):
  File "/usr/local/lib/python3.10/site-packages/nats/aio/client.py", line 1301, in _select_next_server
    await self._transport.connect(
  File "/usr/local/lib/python3.10/site-packages/nats/aio/transport.py", line 118, in connect
    r, w = await asyncio.wait_for(
  File "/usr/local/lib/python3.10/asyncio/tasks.py", line 445, in wait_for
    return fut.result()
  File "/usr/local/lib/python3.10/asyncio/streams.py", line 47, in open_connection
    transport, _ = await loop.create_connection(
  File "/usr/local/lib/python3.10/asyncio/base_events.py", line 1025, in create_connection
    infos = await self._ensure_resolved(
  File "/usr/local/lib/python3.10/asyncio/base_events.py", line 1404, in _ensure_resolved
    return await loop.getaddrinfo(host, port, family=family, type=type,
  File "/usr/local/lib/python3.10/asyncio/base_events.py", line 860, in getaddrinfo
    return await self.run_in_executor(
  File "/usr/local/lib/python3.10/concurrent/futures/thread.py", line 58, in run
    result = self.fn(*self.args, **self.kwargs)
  File "/usr/local/lib/python3.10/socket.py", line 955, in getaddrinfo
    for res in _socket.getaddrinfo(host, port, family, type, proto, flags):
socket.gaierror: [Errno -2] Name or service not known
[32m2022-10-05 16:00:00 +0000[0m - dagster - [34mERROR[0m - [31mdump_to_s3 - 4704635f-cbe5-4de7-9b05-4cf3b0036a5a - 27014 - collect_data - STEP_FAILURE - Execution of step "collect_data" failed.

dagster._core.errors.DagsterExecutionInterruptedError

Stack Trace:
  File "/usr/local/lib/python3.10/site-packages/dagster/_core/execution/plan/execute_plan.py", line 224, in dagster_event_sequence_for_step
    for step_event in check.generator(step_events):
  File "/usr/local/lib/python3.10/site-packages/dagster/_core/execution/plan/execute_step.py", line 357, in core_dagster_event_sequence_for_step
    for user_event in check.generator(
  File "/usr/local/lib/python3.10/site-packages/dagster/_core/execution/plan/execute_step.py", line 69, in _step_output_error_checked_user_event_sequence
    for user_event in user_event_sequence:
  File "/usr/local/lib/python3.10/site-packages/dagster/_core/execution/plan/compute.py", line 174, in execute_core_compute
    for step_output in _yield_compute_results(step_context, inputs, compute_fn):
  File "/usr/local/lib/python3.10/site-packages/dagster/_core/execution/plan/compute.py", line 142, in _yield_compute_results
    for event in iterate_with_context(
  File "/usr/local/lib/python3.10/site-packages/dagster/_utils/__init__.py", line 430, in iterate_with_context
    next_output = next(iterator)
  File "/usr/local/lib/python3.10/site-packages/dagster/_core/execution/plan/compute.py", line 109, in gen_from_async_gen
    yield loop.run_until_complete(async_gen.__anext__())
  File "/usr/local/lib/python3.10/asyncio/base_events.py", line 633, in run_until_complete
    self.run_forever()
  File "/usr/local/lib/python3.10/asyncio/base_events.py", line 600, in run_forever
    self._run_once()
  File "/usr/local/lib/python3.10/asyncio/base_events.py", line 1860, in _run_once
    event_list = self._selector.select(timeout)
  File "/usr/local/lib/python3.10/selectors.py", line 469, in select
    fd_event_list = self._selector.poll(timeout, max_ev)
  File "/usr/local/lib/python3.10/site-packages/dagster/_utils/interrupts.py", line 74, in _new_signal_handler
    raise error_cls()
[0m
