[32m2022-10-23 17:53:18 +0000[0m - dagster - [34mDEBUG[0m - dump_to_s3 - 315581af-9788-4cd5-ba49-3b65c6afd264 - 4774 - collect_messages - LOGS_CAPTURED - Started capturing logs for step: collect_messages.
[32m2022-10-23 17:53:18 +0000[0m - dagster - [34mDEBUG[0m - dump_to_s3 - 315581af-9788-4cd5-ba49-3b65c6afd264 - 4774 - collect_messages - STEP_START - Started execution of step "collect_messages".
[32m2022-10-23 17:53:18 +0000[0m - dagster - [34mDEBUG[0m - dump_to_s3 - 315581af-9788-4cd5-ba49-3b65c6afd264 - 4774 - collect_messages - LOADED_INPUT - Loaded input "create_dump_file" using input manager "io_manager", from output "result" of step "get_interval"
[32m2022-10-23 17:53:18 +0000[0m - dagster - [34mDEBUG[0m - dump_to_s3 - 315581af-9788-4cd5-ba49-3b65c6afd264 - 4774 - collect_messages - STEP_INPUT - Got input "create_dump_file" of type "Tuple[datetime,datetime]". (Type check passed).
nats: encountered error
Traceback (most recent call last):
  File "/usr/local/lib/python3.10/site-packages/nats/aio/client.py", line 1301, in _select_next_server
    await self._transport.connect(
  File "/usr/local/lib/python3.10/site-packages/nats/aio/transport.py", line 118, in connect
    r, w = await asyncio.wait_for(
  File "/usr/local/lib/python3.10/asyncio/tasks.py", line 445, in wait_for
    return fut.result()
  File "/usr/local/lib/python3.10/asyncio/streams.py", line 48, in open_connection
    transport, _ = await loop.create_connection(
  File "/usr/local/lib/python3.10/asyncio/base_events.py", line 1075, in create_connection
    raise OSError('Multiple exceptions: {}'.format(
OSError: Multiple exceptions: [Errno 111] Connect call failed ('127.0.0.1', 4222), [Errno 99] Cannot assign requested address
nats: encountered error
Traceback (most recent call last):
  File "/usr/local/lib/python3.10/site-packages/nats/aio/client.py", line 1301, in _select_next_server
    await self._transport.connect(
  File "/usr/local/lib/python3.10/site-packages/nats/aio/transport.py", line 118, in connect
    r, w = await asyncio.wait_for(
  File "/usr/local/lib/python3.10/asyncio/tasks.py", line 445, in wait_for
    return fut.result()
  File "/usr/local/lib/python3.10/asyncio/streams.py", line 48, in open_connection
    transport, _ = await loop.create_connection(
  File "/usr/local/lib/python3.10/asyncio/base_events.py", line 1075, in create_connection
    raise OSError('Multiple exceptions: {}'.format(
OSError: Multiple exceptions: [Errno 111] Connect call failed ('127.0.0.1', 4222), [Errno 99] Cannot assign requested address
nats: encountered error
Traceback (most recent call last):
  File "/usr/local/lib/python3.10/site-packages/nats/aio/client.py", line 1301, in _select_next_server
    await self._transport.connect(
  File "/usr/local/lib/python3.10/site-packages/nats/aio/transport.py", line 118, in connect
    r, w = await asyncio.wait_for(
  File "/usr/local/lib/python3.10/asyncio/tasks.py", line 445, in wait_for
    return fut.result()
  File "/usr/local/lib/python3.10/asyncio/streams.py", line 48, in open_connection
    transport, _ = await loop.create_connection(
  File "/usr/local/lib/python3.10/asyncio/base_events.py", line 1075, in create_connection
    raise OSError('Multiple exceptions: {}'.format(
OSError: Multiple exceptions: [Errno 111] Connect call failed ('127.0.0.1', 4222), [Errno 99] Cannot assign requested address
nats: encountered error
Traceback (most recent call last):
  File "/usr/local/lib/python3.10/site-packages/nats/aio/client.py", line 1301, in _select_next_server
    await self._transport.connect(
  File "/usr/local/lib/python3.10/site-packages/nats/aio/transport.py", line 118, in connect
    r, w = await asyncio.wait_for(
  File "/usr/local/lib/python3.10/asyncio/tasks.py", line 445, in wait_for
    return fut.result()
  File "/usr/local/lib/python3.10/asyncio/streams.py", line 48, in open_connection
    transport, _ = await loop.create_connection(
  File "/usr/local/lib/python3.10/asyncio/base_events.py", line 1075, in create_connection
    raise OSError('Multiple exceptions: {}'.format(
OSError: Multiple exceptions: [Errno 111] Connect call failed ('127.0.0.1', 4222), [Errno 99] Cannot assign requested address
nats: encountered error
Traceback (most recent call last):
  File "/usr/local/lib/python3.10/site-packages/nats/aio/client.py", line 1301, in _select_next_server
    await self._transport.connect(
  File "/usr/local/lib/python3.10/site-packages/nats/aio/transport.py", line 118, in connect
    r, w = await asyncio.wait_for(
  File "/usr/local/lib/python3.10/asyncio/tasks.py", line 445, in wait_for
    return fut.result()
  File "/usr/local/lib/python3.10/asyncio/streams.py", line 48, in open_connection
    transport, _ = await loop.create_connection(
  File "/usr/local/lib/python3.10/asyncio/base_events.py", line 1075, in create_connection
    raise OSError('Multiple exceptions: {}'.format(
OSError: Multiple exceptions: [Errno 111] Connect call failed ('127.0.0.1', 4222), [Errno 99] Cannot assign requested address
nats: encountered error
Traceback (most recent call last):
  File "/usr/local/lib/python3.10/site-packages/nats/aio/client.py", line 1301, in _select_next_server
    await self._transport.connect(
  File "/usr/local/lib/python3.10/site-packages/nats/aio/transport.py", line 118, in connect
    r, w = await asyncio.wait_for(
  File "/usr/local/lib/python3.10/asyncio/tasks.py", line 445, in wait_for
    return fut.result()
  File "/usr/local/lib/python3.10/asyncio/streams.py", line 48, in open_connection
    transport, _ = await loop.create_connection(
  File "/usr/local/lib/python3.10/asyncio/base_events.py", line 1075, in create_connection
    raise OSError('Multiple exceptions: {}'.format(
OSError: Multiple exceptions: [Errno 111] Connect call failed ('127.0.0.1', 4222), [Errno 99] Cannot assign requested address
nats: encountered error
Traceback (most recent call last):
  File "/usr/local/lib/python3.10/site-packages/nats/aio/client.py", line 1301, in _select_next_server
    await self._transport.connect(
  File "/usr/local/lib/python3.10/site-packages/nats/aio/transport.py", line 118, in connect
    r, w = await asyncio.wait_for(
  File "/usr/local/lib/python3.10/asyncio/tasks.py", line 445, in wait_for
    return fut.result()
  File "/usr/local/lib/python3.10/asyncio/streams.py", line 48, in open_connection
    transport, _ = await loop.create_connection(
  File "/usr/local/lib/python3.10/asyncio/base_events.py", line 1075, in create_connection
    raise OSError('Multiple exceptions: {}'.format(
OSError: Multiple exceptions: [Errno 111] Connect call failed ('127.0.0.1', 4222), [Errno 99] Cannot assign requested address
nats: encountered error
Traceback (most recent call last):
  File "/usr/local/lib/python3.10/site-packages/nats/aio/client.py", line 1301, in _select_next_server
    await self._transport.connect(
  File "/usr/local/lib/python3.10/site-packages/nats/aio/transport.py", line 118, in connect
    r, w = await asyncio.wait_for(
  File "/usr/local/lib/python3.10/asyncio/tasks.py", line 445, in wait_for
    return fut.result()
  File "/usr/local/lib/python3.10/asyncio/streams.py", line 48, in open_connection
    transport, _ = await loop.create_connection(
  File "/usr/local/lib/python3.10/asyncio/base_events.py", line 1075, in create_connection
    raise OSError('Multiple exceptions: {}'.format(
OSError: Multiple exceptions: [Errno 111] Connect call failed ('127.0.0.1', 4222), [Errno 99] Cannot assign requested address
nats: encountered error
Traceback (most recent call last):
  File "/usr/local/lib/python3.10/site-packages/nats/aio/client.py", line 1301, in _select_next_server
    await self._transport.connect(
  File "/usr/local/lib/python3.10/site-packages/nats/aio/transport.py", line 118, in connect
    r, w = await asyncio.wait_for(
  File "/usr/local/lib/python3.10/asyncio/tasks.py", line 445, in wait_for
    return fut.result()
  File "/usr/local/lib/python3.10/asyncio/streams.py", line 48, in open_connection
    transport, _ = await loop.create_connection(
  File "/usr/local/lib/python3.10/asyncio/base_events.py", line 1075, in create_connection
    raise OSError('Multiple exceptions: {}'.format(
OSError: Multiple exceptions: [Errno 111] Connect call failed ('127.0.0.1', 4222), [Errno 99] Cannot assign requested address
nats: encountered error
Traceback (most recent call last):
  File "/usr/local/lib/python3.10/site-packages/nats/aio/client.py", line 1301, in _select_next_server
    await self._transport.connect(
  File "/usr/local/lib/python3.10/site-packages/nats/aio/transport.py", line 118, in connect
    r, w = await asyncio.wait_for(
  File "/usr/local/lib/python3.10/asyncio/tasks.py", line 445, in wait_for
    return fut.result()
  File "/usr/local/lib/python3.10/asyncio/streams.py", line 48, in open_connection
    transport, _ = await loop.create_connection(
  File "/usr/local/lib/python3.10/asyncio/base_events.py", line 1075, in create_connection
    raise OSError('Multiple exceptions: {}'.format(
OSError: Multiple exceptions: [Errno 111] Connect call failed ('127.0.0.1', 4222), [Errno 99] Cannot assign requested address
nats: encountered error
Traceback (most recent call last):
  File "/usr/local/lib/python3.10/site-packages/nats/aio/client.py", line 1301, in _select_next_server
    await self._transport.connect(
  File "/usr/local/lib/python3.10/site-packages/nats/aio/transport.py", line 118, in connect
    r, w = await asyncio.wait_for(
  File "/usr/local/lib/python3.10/asyncio/tasks.py", line 445, in wait_for
    return fut.result()
  File "/usr/local/lib/python3.10/asyncio/streams.py", line 48, in open_connection
    transport, _ = await loop.create_connection(
  File "/usr/local/lib/python3.10/asyncio/base_events.py", line 1075, in create_connection
    raise OSError('Multiple exceptions: {}'.format(
OSError: Multiple exceptions: [Errno 111] Connect call failed ('127.0.0.1', 4222), [Errno 99] Cannot assign requested address
nats: encountered error
Traceback (most recent call last):
  File "/usr/local/lib/python3.10/site-packages/nats/aio/client.py", line 1301, in _select_next_server
    await self._transport.connect(
  File "/usr/local/lib/python3.10/site-packages/nats/aio/transport.py", line 118, in connect
    r, w = await asyncio.wait_for(
  File "/usr/local/lib/python3.10/asyncio/tasks.py", line 445, in wait_for
    return fut.result()
  File "/usr/local/lib/python3.10/asyncio/streams.py", line 48, in open_connection
    transport, _ = await loop.create_connection(
  File "/usr/local/lib/python3.10/asyncio/base_events.py", line 1075, in create_connection
    raise OSError('Multiple exceptions: {}'.format(
OSError: Multiple exceptions: [Errno 111] Connect call failed ('127.0.0.1', 4222), [Errno 99] Cannot assign requested address
nats: encountered error
Traceback (most recent call last):
  File "/usr/local/lib/python3.10/site-packages/nats/aio/client.py", line 1301, in _select_next_server
    await self._transport.connect(
  File "/usr/local/lib/python3.10/site-packages/nats/aio/transport.py", line 118, in connect
    r, w = await asyncio.wait_for(
  File "/usr/local/lib/python3.10/asyncio/tasks.py", line 445, in wait_for
    return fut.result()
  File "/usr/local/lib/python3.10/asyncio/streams.py", line 48, in open_connection
    transport, _ = await loop.create_connection(
  File "/usr/local/lib/python3.10/asyncio/base_events.py", line 1075, in create_connection
    raise OSError('Multiple exceptions: {}'.format(
OSError: Multiple exceptions: [Errno 111] Connect call failed ('127.0.0.1', 4222), [Errno 99] Cannot assign requested address
nats: encountered error
Traceback (most recent call last):
  File "/usr/local/lib/python3.10/site-packages/nats/aio/client.py", line 1301, in _select_next_server
    await self._transport.connect(
  File "/usr/local/lib/python3.10/site-packages/nats/aio/transport.py", line 118, in connect
    r, w = await asyncio.wait_for(
  File "/usr/local/lib/python3.10/asyncio/tasks.py", line 445, in wait_for
    return fut.result()
  File "/usr/local/lib/python3.10/asyncio/streams.py", line 48, in open_connection
    transport, _ = await loop.create_connection(
  File "/usr/local/lib/python3.10/asyncio/base_events.py", line 1075, in create_connection
    raise OSError('Multiple exceptions: {}'.format(
OSError: Multiple exceptions: [Errno 111] Connect call failed ('127.0.0.1', 4222), [Errno 99] Cannot assign requested address
nats: encountered error
Traceback (most recent call last):
  File "/usr/local/lib/python3.10/site-packages/nats/aio/client.py", line 1301, in _select_next_server
    await self._transport.connect(
  File "/usr/local/lib/python3.10/site-packages/nats/aio/transport.py", line 118, in connect
    r, w = await asyncio.wait_for(
  File "/usr/local/lib/python3.10/asyncio/tasks.py", line 445, in wait_for
    return fut.result()
  File "/usr/local/lib/python3.10/asyncio/streams.py", line 48, in open_connection
    transport, _ = await loop.create_connection(
  File "/usr/local/lib/python3.10/asyncio/base_events.py", line 1075, in create_connection
    raise OSError('Multiple exceptions: {}'.format(
OSError: Multiple exceptions: [Errno 111] Connect call failed ('127.0.0.1', 4222), [Errno 99] Cannot assign requested address
nats: encountered error
Traceback (most recent call last):
  File "/usr/local/lib/python3.10/site-packages/nats/aio/client.py", line 1301, in _select_next_server
    await self._transport.connect(
  File "/usr/local/lib/python3.10/site-packages/nats/aio/transport.py", line 118, in connect
    r, w = await asyncio.wait_for(
  File "/usr/local/lib/python3.10/asyncio/tasks.py", line 445, in wait_for
    return fut.result()
  File "/usr/local/lib/python3.10/asyncio/streams.py", line 48, in open_connection
    transport, _ = await loop.create_connection(
  File "/usr/local/lib/python3.10/asyncio/base_events.py", line 1075, in create_connection
    raise OSError('Multiple exceptions: {}'.format(
OSError: Multiple exceptions: [Errno 111] Connect call failed ('127.0.0.1', 4222), [Errno 99] Cannot assign requested address
nats: encountered error
Traceback (most recent call last):
  File "/usr/local/lib/python3.10/site-packages/nats/aio/client.py", line 1301, in _select_next_server
    await self._transport.connect(
  File "/usr/local/lib/python3.10/site-packages/nats/aio/transport.py", line 118, in connect
    r, w = await asyncio.wait_for(
  File "/usr/local/lib/python3.10/asyncio/tasks.py", line 445, in wait_for
    return fut.result()
  File "/usr/local/lib/python3.10/asyncio/streams.py", line 48, in open_connection
    transport, _ = await loop.create_connection(
  File "/usr/local/lib/python3.10/asyncio/base_events.py", line 1075, in create_connection
    raise OSError('Multiple exceptions: {}'.format(
OSError: Multiple exceptions: [Errno 111] Connect call failed ('127.0.0.1', 4222), [Errno 99] Cannot assign requested address
nats: encountered error
Traceback (most recent call last):
  File "/usr/local/lib/python3.10/site-packages/nats/aio/client.py", line 1301, in _select_next_server
    await self._transport.connect(
  File "/usr/local/lib/python3.10/site-packages/nats/aio/transport.py", line 118, in connect
    r, w = await asyncio.wait_for(
  File "/usr/local/lib/python3.10/asyncio/tasks.py", line 445, in wait_for
    return fut.result()
  File "/usr/local/lib/python3.10/asyncio/streams.py", line 48, in open_connection
    transport, _ = await loop.create_connection(
  File "/usr/local/lib/python3.10/asyncio/base_events.py", line 1075, in create_connection
    raise OSError('Multiple exceptions: {}'.format(
OSError: Multiple exceptions: [Errno 111] Connect call failed ('127.0.0.1', 4222), [Errno 99] Cannot assign requested address
nats: encountered error
Traceback (most recent call last):
  File "/usr/local/lib/python3.10/site-packages/nats/aio/client.py", line 1301, in _select_next_server
    await self._transport.connect(
  File "/usr/local/lib/python3.10/site-packages/nats/aio/transport.py", line 118, in connect
    r, w = await asyncio.wait_for(
  File "/usr/local/lib/python3.10/asyncio/tasks.py", line 445, in wait_for
    return fut.result()
  File "/usr/local/lib/python3.10/asyncio/streams.py", line 48, in open_connection
    transport, _ = await loop.create_connection(
  File "/usr/local/lib/python3.10/asyncio/base_events.py", line 1075, in create_connection
    raise OSError('Multiple exceptions: {}'.format(
OSError: Multiple exceptions: [Errno 111] Connect call failed ('127.0.0.1', 4222), [Errno 99] Cannot assign requested address
nats: encountered error
Traceback (most recent call last):
  File "/usr/local/lib/python3.10/site-packages/nats/aio/client.py", line 1301, in _select_next_server
    await self._transport.connect(
  File "/usr/local/lib/python3.10/site-packages/nats/aio/transport.py", line 118, in connect
    r, w = await asyncio.wait_for(
  File "/usr/local/lib/python3.10/asyncio/tasks.py", line 445, in wait_for
    return fut.result()
  File "/usr/local/lib/python3.10/asyncio/streams.py", line 48, in open_connection
    transport, _ = await loop.create_connection(
  File "/usr/local/lib/python3.10/asyncio/base_events.py", line 1075, in create_connection
    raise OSError('Multiple exceptions: {}'.format(
OSError: Multiple exceptions: [Errno 111] Connect call failed ('127.0.0.1', 4222), [Errno 99] Cannot assign requested address
nats: encountered error
Traceback (most recent call last):
  File "/usr/local/lib/python3.10/site-packages/nats/aio/client.py", line 1301, in _select_next_server
    await self._transport.connect(
  File "/usr/local/lib/python3.10/site-packages/nats/aio/transport.py", line 118, in connect
    r, w = await asyncio.wait_for(
  File "/usr/local/lib/python3.10/asyncio/tasks.py", line 445, in wait_for
    return fut.result()
  File "/usr/local/lib/python3.10/asyncio/streams.py", line 48, in open_connection
    transport, _ = await loop.create_connection(
  File "/usr/local/lib/python3.10/asyncio/base_events.py", line 1075, in create_connection
    raise OSError('Multiple exceptions: {}'.format(
OSError: Multiple exceptions: [Errno 111] Connect call failed ('127.0.0.1', 4222), [Errno 99] Cannot assign requested address
nats: encountered error
Traceback (most recent call last):
  File "/usr/local/lib/python3.10/site-packages/nats/aio/client.py", line 1301, in _select_next_server
    await self._transport.connect(
  File "/usr/local/lib/python3.10/site-packages/nats/aio/transport.py", line 118, in connect
    r, w = await asyncio.wait_for(
  File "/usr/local/lib/python3.10/asyncio/tasks.py", line 445, in wait_for
    return fut.result()
  File "/usr/local/lib/python3.10/asyncio/streams.py", line 48, in open_connection
    transport, _ = await loop.create_connection(
  File "/usr/local/lib/python3.10/asyncio/base_events.py", line 1075, in create_connection
    raise OSError('Multiple exceptions: {}'.format(
OSError: Multiple exceptions: [Errno 111] Connect call failed ('127.0.0.1', 4222), [Errno 99] Cannot assign requested address
nats: encountered error
Traceback (most recent call last):
  File "/usr/local/lib/python3.10/site-packages/nats/aio/client.py", line 1301, in _select_next_server
    await self._transport.connect(
  File "/usr/local/lib/python3.10/site-packages/nats/aio/transport.py", line 118, in connect
    r, w = await asyncio.wait_for(
  File "/usr/local/lib/python3.10/asyncio/tasks.py", line 445, in wait_for
    return fut.result()
  File "/usr/local/lib/python3.10/asyncio/streams.py", line 48, in open_connection
    transport, _ = await loop.create_connection(
  File "/usr/local/lib/python3.10/asyncio/base_events.py", line 1075, in create_connection
    raise OSError('Multiple exceptions: {}'.format(
OSError: Multiple exceptions: [Errno 111] Connect call failed ('127.0.0.1', 4222), [Errno 99] Cannot assign requested address
nats: encountered error
Traceback (most recent call last):
  File "/usr/local/lib/python3.10/site-packages/nats/aio/client.py", line 1301, in _select_next_server
    await self._transport.connect(
  File "/usr/local/lib/python3.10/site-packages/nats/aio/transport.py", line 118, in connect
    r, w = await asyncio.wait_for(
  File "/usr/local/lib/python3.10/asyncio/tasks.py", line 445, in wait_for
    return fut.result()
  File "/usr/local/lib/python3.10/asyncio/streams.py", line 48, in open_connection
    transport, _ = await loop.create_connection(
  File "/usr/local/lib/python3.10/asyncio/base_events.py", line 1075, in create_connection
    raise OSError('Multiple exceptions: {}'.format(
OSError: Multiple exceptions: [Errno 111] Connect call failed ('127.0.0.1', 4222), [Errno 99] Cannot assign requested address
nats: encountered error
Traceback (most recent call last):
  File "/usr/local/lib/python3.10/site-packages/nats/aio/client.py", line 1301, in _select_next_server
    await self._transport.connect(
  File "/usr/local/lib/python3.10/site-packages/nats/aio/transport.py", line 118, in connect
    r, w = await asyncio.wait_for(
  File "/usr/local/lib/python3.10/asyncio/tasks.py", line 445, in wait_for
    return fut.result()
  File "/usr/local/lib/python3.10/asyncio/streams.py", line 48, in open_connection
    transport, _ = await loop.create_connection(
  File "/usr/local/lib/python3.10/asyncio/base_events.py", line 1075, in create_connection
    raise OSError('Multiple exceptions: {}'.format(
OSError: Multiple exceptions: [Errno 111] Connect call failed ('127.0.0.1', 4222), [Errno 99] Cannot assign requested address
nats: encountered error
Traceback (most recent call last):
  File "/usr/local/lib/python3.10/site-packages/nats/aio/client.py", line 1301, in _select_next_server
    await self._transport.connect(
  File "/usr/local/lib/python3.10/site-packages/nats/aio/transport.py", line 118, in connect
    r, w = await asyncio.wait_for(
  File "/usr/local/lib/python3.10/asyncio/tasks.py", line 445, in wait_for
    return fut.result()
  File "/usr/local/lib/python3.10/asyncio/streams.py", line 48, in open_connection
    transport, _ = await loop.create_connection(
  File "/usr/local/lib/python3.10/asyncio/base_events.py", line 1075, in create_connection
    raise OSError('Multiple exceptions: {}'.format(
OSError: Multiple exceptions: [Errno 111] Connect call failed ('127.0.0.1', 4222), [Errno 99] Cannot assign requested address
nats: encountered error
Traceback (most recent call last):
  File "/usr/local/lib/python3.10/site-packages/nats/aio/client.py", line 1301, in _select_next_server
    await self._transport.connect(
  File "/usr/local/lib/python3.10/site-packages/nats/aio/transport.py", line 118, in connect
    r, w = await asyncio.wait_for(
  File "/usr/local/lib/python3.10/asyncio/tasks.py", line 445, in wait_for
    return fut.result()
  File "/usr/local/lib/python3.10/asyncio/streams.py", line 48, in open_connection
    transport, _ = await loop.create_connection(
  File "/usr/local/lib/python3.10/asyncio/base_events.py", line 1075, in create_connection
    raise OSError('Multiple exceptions: {}'.format(
OSError: Multiple exceptions: [Errno 111] Connect call failed ('127.0.0.1', 4222), [Errno 99] Cannot assign requested address
nats: encountered error
Traceback (most recent call last):
  File "/usr/local/lib/python3.10/site-packages/nats/aio/client.py", line 1301, in _select_next_server
    await self._transport.connect(
  File "/usr/local/lib/python3.10/site-packages/nats/aio/transport.py", line 118, in connect
    r, w = await asyncio.wait_for(
  File "/usr/local/lib/python3.10/asyncio/tasks.py", line 445, in wait_for
    return fut.result()
  File "/usr/local/lib/python3.10/asyncio/streams.py", line 48, in open_connection
    transport, _ = await loop.create_connection(
  File "/usr/local/lib/python3.10/asyncio/base_events.py", line 1075, in create_connection
    raise OSError('Multiple exceptions: {}'.format(
OSError: Multiple exceptions: [Errno 111] Connect call failed ('127.0.0.1', 4222), [Errno 99] Cannot assign requested address
nats: encountered error
Traceback (most recent call last):
  File "/usr/local/lib/python3.10/site-packages/nats/aio/client.py", line 1301, in _select_next_server
    await self._transport.connect(
  File "/usr/local/lib/python3.10/site-packages/nats/aio/transport.py", line 118, in connect
    r, w = await asyncio.wait_for(
  File "/usr/local/lib/python3.10/asyncio/tasks.py", line 445, in wait_for
    return fut.result()
  File "/usr/local/lib/python3.10/asyncio/streams.py", line 48, in open_connection
    transport, _ = await loop.create_connection(
  File "/usr/local/lib/python3.10/asyncio/base_events.py", line 1075, in create_connection
    raise OSError('Multiple exceptions: {}'.format(
OSError: Multiple exceptions: [Errno 111] Connect call failed ('127.0.0.1', 4222), [Errno 99] Cannot assign requested address
nats: encountered error
Traceback (most recent call last):
  File "/usr/local/lib/python3.10/site-packages/nats/aio/client.py", line 1301, in _select_next_server
    await self._transport.connect(
  File "/usr/local/lib/python3.10/site-packages/nats/aio/transport.py", line 118, in connect
    r, w = await asyncio.wait_for(
  File "/usr/local/lib/python3.10/asyncio/tasks.py", line 445, in wait_for
    return fut.result()
  File "/usr/local/lib/python3.10/asyncio/streams.py", line 48, in open_connection
    transport, _ = await loop.create_connection(
  File "/usr/local/lib/python3.10/asyncio/base_events.py", line 1075, in create_connection
    raise OSError('Multiple exceptions: {}'.format(
OSError: Multiple exceptions: [Errno 111] Connect call failed ('127.0.0.1', 4222), [Errno 99] Cannot assign requested address
nats: encountered error
Traceback (most recent call last):
  File "/usr/local/lib/python3.10/site-packages/nats/aio/client.py", line 1301, in _select_next_server
    await self._transport.connect(
  File "/usr/local/lib/python3.10/site-packages/nats/aio/transport.py", line 118, in connect
    r, w = await asyncio.wait_for(
  File "/usr/local/lib/python3.10/asyncio/tasks.py", line 445, in wait_for
    return fut.result()
  File "/usr/local/lib/python3.10/asyncio/streams.py", line 48, in open_connection
    transport, _ = await loop.create_connection(
  File "/usr/local/lib/python3.10/asyncio/base_events.py", line 1075, in create_connection
    raise OSError('Multiple exceptions: {}'.format(
OSError: Multiple exceptions: [Errno 111] Connect call failed ('127.0.0.1', 4222), [Errno 99] Cannot assign requested address
nats: encountered error
Traceback (most recent call last):
  File "/usr/local/lib/python3.10/site-packages/nats/aio/client.py", line 1301, in _select_next_server
    await self._transport.connect(
  File "/usr/local/lib/python3.10/site-packages/nats/aio/transport.py", line 118, in connect
    r, w = await asyncio.wait_for(
  File "/usr/local/lib/python3.10/asyncio/tasks.py", line 445, in wait_for
    return fut.result()
  File "/usr/local/lib/python3.10/asyncio/streams.py", line 48, in open_connection
    transport, _ = await loop.create_connection(
  File "/usr/local/lib/python3.10/asyncio/base_events.py", line 1075, in create_connection
    raise OSError('Multiple exceptions: {}'.format(
OSError: Multiple exceptions: [Errno 111] Connect call failed ('127.0.0.1', 4222), [Errno 99] Cannot assign requested address
[32m2022-10-23 17:54:20 +0000[0m - dagster - [34mERROR[0m - [31mdump_to_s3 - 315581af-9788-4cd5-ba49-3b65c6afd264 - 4774 - collect_messages - STEP_FAILURE - Execution of step "collect_messages" failed.

dagster._core.errors.DagsterExecutionInterruptedError

Stack Trace:
  File "/usr/local/lib/python3.10/site-packages/dagster/_core/execution/plan/execute_plan.py", line 225, in dagster_event_sequence_for_step
    for step_event in check.generator(step_events):
  File "/usr/local/lib/python3.10/site-packages/dagster/_core/execution/plan/execute_step.py", line 360, in core_dagster_event_sequence_for_step
    for user_event in check.generator(
  File "/usr/local/lib/python3.10/site-packages/dagster/_core/execution/plan/execute_step.py", line 69, in _step_output_error_checked_user_event_sequence
    for user_event in user_event_sequence:
  File "/usr/local/lib/python3.10/site-packages/dagster/_core/execution/plan/compute.py", line 174, in execute_core_compute
    for step_output in _yield_compute_results(step_context, inputs, compute_fn):
  File "/usr/local/lib/python3.10/site-packages/dagster/_core/execution/plan/compute.py", line 142, in _yield_compute_results
    for event in iterate_with_context(
  File "/usr/local/lib/python3.10/site-packages/dagster/_utils/__init__.py", line 430, in iterate_with_context
    next_output = next(iterator)
  File "/usr/local/lib/python3.10/site-packages/dagster/_core/execution/plan/compute.py", line 109, in gen_from_async_gen
    yield loop.run_until_complete(async_gen.__anext__())
  File "/usr/local/lib/python3.10/asyncio/base_events.py", line 636, in run_until_complete
    self.run_forever()
  File "/usr/local/lib/python3.10/asyncio/base_events.py", line 603, in run_forever
    self._run_once()
  File "/usr/local/lib/python3.10/asyncio/base_events.py", line 1863, in _run_once
    event_list = self._selector.select(timeout)
  File "/usr/local/lib/python3.10/selectors.py", line 469, in select
    fd_event_list = self._selector.poll(timeout, max_ev)
  File "/usr/local/lib/python3.10/site-packages/dagster/_utils/interrupts.py", line 74, in _new_signal_handler
    raise error_cls()
[0m
