[32m2022-10-23 20:35:34 +0000[0m - dagster - [34mDEBUG[0m - __ASSET_JOB - d470649e-4aaa-4ced-b875-89b024792f17 - 23032 - ais_messages - LOGS_CAPTURED - Started capturing logs for step: ais_messages.
[32m2022-10-23 20:35:34 +0000[0m - dagster - [34mDEBUG[0m - __ASSET_JOB - d470649e-4aaa-4ced-b875-89b024792f17 - 23032 - ais_messages - STEP_START - Started execution of step "ais_messages".
[32m2022-10-23 20:35:34 +0000[0m - dagster - [34mERROR[0m - [31m__ASSET_JOB - d470649e-4aaa-4ced-b875-89b024792f17 - 23032 - ais_messages - STEP_FAILURE - Execution of step "ais_messages" failed.

dagster._core.errors.DagsterUnknownResourceError: Unknown resource `nats_client`. Specify `nats_client` as a required resource on the compute / config function that accessed it.

Stack Trace:
  File "/usr/local/lib/python3.10/site-packages/dagster/_core/execution/plan/execute_plan.py", line 225, in dagster_event_sequence_for_step
    for step_event in check.generator(step_events):
  File "/usr/local/lib/python3.10/site-packages/dagster/_core/execution/plan/execute_step.py", line 360, in core_dagster_event_sequence_for_step
    for user_event in check.generator(
  File "/usr/local/lib/python3.10/site-packages/dagster/_core/execution/plan/execute_step.py", line 69, in _step_output_error_checked_user_event_sequence
    for user_event in user_event_sequence:
  File "/usr/local/lib/python3.10/site-packages/dagster/_core/execution/plan/compute.py", line 174, in execute_core_compute
    for step_output in _yield_compute_results(step_context, inputs, compute_fn):
  File "/usr/local/lib/python3.10/site-packages/dagster/_core/execution/plan/compute.py", line 142, in _yield_compute_results
    for event in iterate_with_context(
  File "/usr/local/lib/python3.10/site-packages/dagster/_utils/__init__.py", line 430, in iterate_with_context
    next_output = next(iterator)
  File "/usr/local/lib/python3.10/site-packages/dagster/_core/execution/plan/compute.py", line 109, in gen_from_async_gen
    yield loop.run_until_complete(async_gen.__anext__())
  File "/usr/local/lib/python3.10/asyncio/base_events.py", line 649, in run_until_complete
    return future.result()
  File "/usr/local/lib/python3.10/site-packages/dagster/_core/execution/plan/compute_generator.py", line 68, in _coerce_async_solid_to_async_gen
    result = await awaitable
  File "/workspaces/pipeline-environment/dagster_ais/dagster_ais/assets/trajectory_assets.py", line 20, in ais_messages
    nats_conn = context.resources.nats_client
  File "/usr/local/lib/python3.10/site-packages/dagster/_core/definitions/scoped_resources_builder.py", line 100, in __getattr__
    raise DagsterUnknownResourceError(attr)
[0m
