[2022-10-05T09:24:09.379+0000] {taskinstance.py:1165} INFO - Dependencies all met for <TaskInstance: dump_to_s3.collect_messages manual__2022-10-05T09:24:05.089192+00:00 [queued]>
[2022-10-05T09:24:09.387+0000] {taskinstance.py:1165} INFO - Dependencies all met for <TaskInstance: dump_to_s3.collect_messages manual__2022-10-05T09:24:05.089192+00:00 [queued]>
[2022-10-05T09:24:09.387+0000] {taskinstance.py:1362} INFO - 
--------------------------------------------------------------------------------
[2022-10-05T09:24:09.387+0000] {taskinstance.py:1363} INFO - Starting attempt 1 of 1
[2022-10-05T09:24:09.387+0000] {taskinstance.py:1364} INFO - 
--------------------------------------------------------------------------------
[2022-10-05T09:24:09.455+0000] {taskinstance.py:1383} INFO - Executing <Task(_PythonDecoratedOperator): collect_messages> on 2022-10-05 09:24:05.089192+00:00
[2022-10-05T09:24:09.458+0000] {standard_task_runner.py:54} INFO - Started process 31725 to run task
[2022-10-05T09:24:09.461+0000] {standard_task_runner.py:82} INFO - Running: ['airflow', 'tasks', 'run', 'dump_to_s3', 'collect_messages', 'manual__2022-10-05T09:24:05.089192+00:00', '--job-id', '42', '--raw', '--subdir', 'DAGS_FOLDER/pipeline.py', '--cfg-path', '/tmp/tmpu3uvh6yb']
[2022-10-05T09:24:09.462+0000] {standard_task_runner.py:83} INFO - Job 42: Subtask collect_messages
[2022-10-05T09:24:09.464+0000] {dagbag.py:525} INFO - Filling up the DagBag from /workspaces/pipeline-environment/test_airflow/dags/pipeline.py
[2022-10-05T09:24:09.549+0000] {logging_mixin.py:117} WARNING - /usr/local/lib/python3.10/site-packages/airflow/models/dag.py:3393 RemovedInAirflow3Warning: Param `schedule_interval` is deprecated and will be removed in a future release. Please use `schedule` instead.
[2022-10-05T09:24:09.551+0000] {taskmixin.py:205} WARNING - Dependency <Task(_PythonDecoratedOperator): create_dump_file>, collect_messages already registered for DAG: dump_to_s3
[2022-10-05T09:24:09.552+0000] {taskmixin.py:205} WARNING - Dependency <Task(_PythonDecoratedOperator): collect_messages>, create_dump_file already registered for DAG: dump_to_s3
[2022-10-05T09:24:09.552+0000] {taskmixin.py:205} WARNING - Dependency <Task(_PythonDecoratedOperator): create_dump_file>, collect_messages already registered for DAG: dump_to_s3
[2022-10-05T09:24:09.552+0000] {taskmixin.py:205} WARNING - Dependency <Task(_PythonDecoratedOperator): collect_messages>, create_dump_file already registered for DAG: dump_to_s3
[2022-10-05T09:24:09.552+0000] {taskmixin.py:205} WARNING - Dependency <Task(_PythonDecoratedOperator): create_dump_file>, collect_messages already registered for DAG: dump_to_s3
[2022-10-05T09:24:09.552+0000] {taskmixin.py:205} WARNING - Dependency <Task(_PythonDecoratedOperator): collect_messages>, create_dump_file already registered for DAG: dump_to_s3
[2022-10-05T09:24:09.553+0000] {taskmixin.py:205} WARNING - Dependency <Task(_PythonDecoratedOperator): create_dump_file>, collect_messages already registered for DAG: dump_to_s3
[2022-10-05T09:24:09.553+0000] {taskmixin.py:205} WARNING - Dependency <Task(_PythonDecoratedOperator): collect_messages>, create_dump_file already registered for DAG: dump_to_s3
[2022-10-05T09:24:09.553+0000] {taskmixin.py:205} WARNING - Dependency <Task(_PythonDecoratedOperator): create_dump_file>, collect_messages already registered for DAG: dump_to_s3
[2022-10-05T09:24:09.553+0000] {taskmixin.py:205} WARNING - Dependency <Task(_PythonDecoratedOperator): collect_messages>, create_dump_file already registered for DAG: dump_to_s3
[2022-10-05T09:24:09.553+0000] {taskmixin.py:205} WARNING - Dependency <Task(_PythonDecoratedOperator): create_dump_file>, collect_messages already registered for DAG: dump_to_s3
[2022-10-05T09:24:09.553+0000] {taskmixin.py:205} WARNING - Dependency <Task(_PythonDecoratedOperator): collect_messages>, create_dump_file already registered for DAG: dump_to_s3
[2022-10-05T09:24:09.554+0000] {taskmixin.py:205} WARNING - Dependency <Task(_PythonDecoratedOperator): collect_messages>, dump_to_s3 already registered for DAG: dump_to_s3
[2022-10-05T09:24:09.554+0000] {taskmixin.py:205} WARNING - Dependency <Task(_PythonDecoratedOperator): dump_to_s3>, collect_messages already registered for DAG: dump_to_s3
[2022-10-05T09:24:09.554+0000] {taskmixin.py:205} WARNING - Dependency <Task(_PythonDecoratedOperator): collect_messages>, dump_to_s3 already registered for DAG: dump_to_s3
[2022-10-05T09:24:09.555+0000] {taskmixin.py:205} WARNING - Dependency <Task(_PythonDecoratedOperator): dump_to_s3>, collect_messages already registered for DAG: dump_to_s3
[2022-10-05T09:24:09.555+0000] {taskmixin.py:205} WARNING - Dependency <Task(_PythonDecoratedOperator): collect_messages>, dump_to_s3 already registered for DAG: dump_to_s3
[2022-10-05T09:24:09.555+0000] {taskmixin.py:205} WARNING - Dependency <Task(_PythonDecoratedOperator): dump_to_s3>, collect_messages already registered for DAG: dump_to_s3
[2022-10-05T09:24:09.555+0000] {taskmixin.py:205} WARNING - Dependency <Task(_PythonDecoratedOperator): collect_messages>, dump_to_s3 already registered for DAG: dump_to_s3
[2022-10-05T09:24:09.555+0000] {taskmixin.py:205} WARNING - Dependency <Task(_PythonDecoratedOperator): dump_to_s3>, collect_messages already registered for DAG: dump_to_s3
[2022-10-05T09:24:09.555+0000] {taskmixin.py:205} WARNING - Dependency <Task(_PythonDecoratedOperator): collect_messages>, dump_to_s3 already registered for DAG: dump_to_s3
[2022-10-05T09:24:09.556+0000] {taskmixin.py:205} WARNING - Dependency <Task(_PythonDecoratedOperator): dump_to_s3>, collect_messages already registered for DAG: dump_to_s3
[2022-10-05T09:24:09.556+0000] {taskmixin.py:205} WARNING - Dependency <Task(_PythonDecoratedOperator): collect_messages>, dump_to_s3 already registered for DAG: dump_to_s3
[2022-10-05T09:24:09.556+0000] {taskmixin.py:205} WARNING - Dependency <Task(_PythonDecoratedOperator): dump_to_s3>, collect_messages already registered for DAG: dump_to_s3
[2022-10-05T09:24:09.621+0000] {task_command.py:384} INFO - Running <TaskInstance: dump_to_s3.collect_messages manual__2022-10-05T09:24:05.089192+00:00 [running]> on host b44ee3804a1a
[2022-10-05T09:24:09.713+0000] {taskinstance.py:1590} INFO - Exporting the following env vars:
AIRFLOW_CTX_DAG_OWNER=airflow
AIRFLOW_CTX_DAG_ID=dump_to_s3
AIRFLOW_CTX_TASK_ID=collect_messages
AIRFLOW_CTX_EXECUTION_DATE=2022-10-05T09:24:05.089192+00:00
AIRFLOW_CTX_TRY_NUMBER=1
AIRFLOW_CTX_DAG_RUN_ID=manual__2022-10-05T09:24:05.089192+00:00
[2022-10-05T09:24:09.747+0000] {client.py:181} ERROR - nats: encountered error
Traceback (most recent call last):
  File "/usr/local/lib/python3.10/site-packages/nats/aio/client.py", line 1301, in _select_next_server
    await self._transport.connect(
  File "/usr/local/lib/python3.10/site-packages/nats/aio/transport.py", line 118, in connect
    r, w = await asyncio.wait_for(
  File "/usr/local/lib/python3.10/asyncio/tasks.py", line 445, in wait_for
    return fut.result()
  File "/usr/local/lib/python3.10/asyncio/streams.py", line 47, in open_connection
    transport, _ = await loop.create_connection(
  File "/usr/local/lib/python3.10/asyncio/base_events.py", line 1025, in create_connection
    infos = await self._ensure_resolved(
  File "/usr/local/lib/python3.10/asyncio/base_events.py", line 1404, in _ensure_resolved
    return await loop.getaddrinfo(host, port, family=family, type=type,
  File "/usr/local/lib/python3.10/asyncio/base_events.py", line 860, in getaddrinfo
    return await self.run_in_executor(
  File "/usr/local/lib/python3.10/concurrent/futures/thread.py", line 58, in run
    result = self.fn(*self.args, **self.kwargs)
  File "/usr/local/lib/python3.10/socket.py", line 955, in getaddrinfo
    for res in _socket.getaddrinfo(host, port, family, type, proto, flags):
socket.gaierror: [Errno -2] Name or service not known
[2022-10-05T09:24:11.791+0000] {client.py:181} ERROR - nats: encountered error
Traceback (most recent call last):
  File "/usr/local/lib/python3.10/site-packages/nats/aio/client.py", line 1301, in _select_next_server
    await self._transport.connect(
  File "/usr/local/lib/python3.10/site-packages/nats/aio/transport.py", line 118, in connect
    r, w = await asyncio.wait_for(
  File "/usr/local/lib/python3.10/asyncio/tasks.py", line 445, in wait_for
    return fut.result()
  File "/usr/local/lib/python3.10/asyncio/streams.py", line 47, in open_connection
    transport, _ = await loop.create_connection(
  File "/usr/local/lib/python3.10/asyncio/base_events.py", line 1025, in create_connection
    infos = await self._ensure_resolved(
  File "/usr/local/lib/python3.10/asyncio/base_events.py", line 1404, in _ensure_resolved
    return await loop.getaddrinfo(host, port, family=family, type=type,
  File "/usr/local/lib/python3.10/asyncio/base_events.py", line 860, in getaddrinfo
    return await self.run_in_executor(
  File "/usr/local/lib/python3.10/concurrent/futures/thread.py", line 58, in run
    result = self.fn(*self.args, **self.kwargs)
  File "/usr/local/lib/python3.10/socket.py", line 955, in getaddrinfo
    for res in _socket.getaddrinfo(host, port, family, type, proto, flags):
socket.gaierror: [Errno -2] Name or service not known
[2022-10-05T09:24:13.806+0000] {client.py:181} ERROR - nats: encountered error
Traceback (most recent call last):
  File "/usr/local/lib/python3.10/site-packages/nats/aio/client.py", line 1301, in _select_next_server
    await self._transport.connect(
  File "/usr/local/lib/python3.10/site-packages/nats/aio/transport.py", line 118, in connect
    r, w = await asyncio.wait_for(
  File "/usr/local/lib/python3.10/asyncio/tasks.py", line 445, in wait_for
    return fut.result()
  File "/usr/local/lib/python3.10/asyncio/streams.py", line 47, in open_connection
    transport, _ = await loop.create_connection(
  File "/usr/local/lib/python3.10/asyncio/base_events.py", line 1025, in create_connection
    infos = await self._ensure_resolved(
  File "/usr/local/lib/python3.10/asyncio/base_events.py", line 1404, in _ensure_resolved
    return await loop.getaddrinfo(host, port, family=family, type=type,
  File "/usr/local/lib/python3.10/asyncio/base_events.py", line 860, in getaddrinfo
    return await self.run_in_executor(
  File "/usr/local/lib/python3.10/concurrent/futures/thread.py", line 58, in run
    result = self.fn(*self.args, **self.kwargs)
  File "/usr/local/lib/python3.10/socket.py", line 955, in getaddrinfo
    for res in _socket.getaddrinfo(host, port, family, type, proto, flags):
socket.gaierror: [Errno -2] Name or service not known
[2022-10-05T09:24:15.820+0000] {client.py:181} ERROR - nats: encountered error
Traceback (most recent call last):
  File "/usr/local/lib/python3.10/site-packages/nats/aio/client.py", line 1301, in _select_next_server
    await self._transport.connect(
  File "/usr/local/lib/python3.10/site-packages/nats/aio/transport.py", line 118, in connect
    r, w = await asyncio.wait_for(
  File "/usr/local/lib/python3.10/asyncio/tasks.py", line 445, in wait_for
    return fut.result()
  File "/usr/local/lib/python3.10/asyncio/streams.py", line 47, in open_connection
    transport, _ = await loop.create_connection(
  File "/usr/local/lib/python3.10/asyncio/base_events.py", line 1025, in create_connection
    infos = await self._ensure_resolved(
  File "/usr/local/lib/python3.10/asyncio/base_events.py", line 1404, in _ensure_resolved
    return await loop.getaddrinfo(host, port, family=family, type=type,
  File "/usr/local/lib/python3.10/asyncio/base_events.py", line 860, in getaddrinfo
    return await self.run_in_executor(
  File "/usr/local/lib/python3.10/concurrent/futures/thread.py", line 58, in run
    result = self.fn(*self.args, **self.kwargs)
  File "/usr/local/lib/python3.10/socket.py", line 955, in getaddrinfo
    for res in _socket.getaddrinfo(host, port, family, type, proto, flags):
socket.gaierror: [Errno -2] Name or service not known
[2022-10-05T09:24:17.843+0000] {client.py:181} ERROR - nats: encountered error
Traceback (most recent call last):
  File "/usr/local/lib/python3.10/site-packages/nats/aio/client.py", line 1301, in _select_next_server
    await self._transport.connect(
  File "/usr/local/lib/python3.10/site-packages/nats/aio/transport.py", line 118, in connect
    r, w = await asyncio.wait_for(
  File "/usr/local/lib/python3.10/asyncio/tasks.py", line 445, in wait_for
    return fut.result()
  File "/usr/local/lib/python3.10/asyncio/streams.py", line 47, in open_connection
    transport, _ = await loop.create_connection(
  File "/usr/local/lib/python3.10/asyncio/base_events.py", line 1025, in create_connection
    infos = await self._ensure_resolved(
  File "/usr/local/lib/python3.10/asyncio/base_events.py", line 1404, in _ensure_resolved
    return await loop.getaddrinfo(host, port, family=family, type=type,
  File "/usr/local/lib/python3.10/asyncio/base_events.py", line 860, in getaddrinfo
    return await self.run_in_executor(
  File "/usr/local/lib/python3.10/concurrent/futures/thread.py", line 58, in run
    result = self.fn(*self.args, **self.kwargs)
  File "/usr/local/lib/python3.10/socket.py", line 955, in getaddrinfo
    for res in _socket.getaddrinfo(host, port, family, type, proto, flags):
socket.gaierror: [Errno -2] Name or service not known
[2022-10-05T09:24:19.867+0000] {client.py:181} ERROR - nats: encountered error
Traceback (most recent call last):
  File "/usr/local/lib/python3.10/site-packages/nats/aio/client.py", line 1301, in _select_next_server
    await self._transport.connect(
  File "/usr/local/lib/python3.10/site-packages/nats/aio/transport.py", line 118, in connect
    r, w = await asyncio.wait_for(
  File "/usr/local/lib/python3.10/asyncio/tasks.py", line 445, in wait_for
    return fut.result()
  File "/usr/local/lib/python3.10/asyncio/streams.py", line 47, in open_connection
    transport, _ = await loop.create_connection(
  File "/usr/local/lib/python3.10/asyncio/base_events.py", line 1025, in create_connection
    infos = await self._ensure_resolved(
  File "/usr/local/lib/python3.10/asyncio/base_events.py", line 1404, in _ensure_resolved
    return await loop.getaddrinfo(host, port, family=family, type=type,
  File "/usr/local/lib/python3.10/asyncio/base_events.py", line 860, in getaddrinfo
    return await self.run_in_executor(
  File "/usr/local/lib/python3.10/concurrent/futures/thread.py", line 58, in run
    result = self.fn(*self.args, **self.kwargs)
  File "/usr/local/lib/python3.10/socket.py", line 955, in getaddrinfo
    for res in _socket.getaddrinfo(host, port, family, type, proto, flags):
socket.gaierror: [Errno -2] Name or service not known
[2022-10-05T09:24:21.971+0000] {client.py:181} ERROR - nats: encountered error
Traceback (most recent call last):
  File "/usr/local/lib/python3.10/site-packages/nats/aio/client.py", line 1301, in _select_next_server
    await self._transport.connect(
  File "/usr/local/lib/python3.10/site-packages/nats/aio/transport.py", line 118, in connect
    r, w = await asyncio.wait_for(
  File "/usr/local/lib/python3.10/asyncio/tasks.py", line 445, in wait_for
    return fut.result()
  File "/usr/local/lib/python3.10/asyncio/streams.py", line 47, in open_connection
    transport, _ = await loop.create_connection(
  File "/usr/local/lib/python3.10/asyncio/base_events.py", line 1025, in create_connection
    infos = await self._ensure_resolved(
  File "/usr/local/lib/python3.10/asyncio/base_events.py", line 1404, in _ensure_resolved
    return await loop.getaddrinfo(host, port, family=family, type=type,
  File "/usr/local/lib/python3.10/asyncio/base_events.py", line 860, in getaddrinfo
    return await self.run_in_executor(
  File "/usr/local/lib/python3.10/concurrent/futures/thread.py", line 58, in run
    result = self.fn(*self.args, **self.kwargs)
  File "/usr/local/lib/python3.10/socket.py", line 955, in getaddrinfo
    for res in _socket.getaddrinfo(host, port, family, type, proto, flags):
socket.gaierror: [Errno -2] Name or service not known
[2022-10-05T09:24:23.980+0000] {client.py:181} ERROR - nats: encountered error
Traceback (most recent call last):
  File "/usr/local/lib/python3.10/site-packages/nats/aio/client.py", line 1301, in _select_next_server
    await self._transport.connect(
  File "/usr/local/lib/python3.10/site-packages/nats/aio/transport.py", line 118, in connect
    r, w = await asyncio.wait_for(
  File "/usr/local/lib/python3.10/asyncio/tasks.py", line 445, in wait_for
    return fut.result()
  File "/usr/local/lib/python3.10/asyncio/streams.py", line 47, in open_connection
    transport, _ = await loop.create_connection(
  File "/usr/local/lib/python3.10/asyncio/base_events.py", line 1025, in create_connection
    infos = await self._ensure_resolved(
  File "/usr/local/lib/python3.10/asyncio/base_events.py", line 1404, in _ensure_resolved
    return await loop.getaddrinfo(host, port, family=family, type=type,
  File "/usr/local/lib/python3.10/asyncio/base_events.py", line 860, in getaddrinfo
    return await self.run_in_executor(
  File "/usr/local/lib/python3.10/concurrent/futures/thread.py", line 58, in run
    result = self.fn(*self.args, **self.kwargs)
  File "/usr/local/lib/python3.10/socket.py", line 955, in getaddrinfo
    for res in _socket.getaddrinfo(host, port, family, type, proto, flags):
socket.gaierror: [Errno -2] Name or service not known
[2022-10-05T09:24:26.002+0000] {client.py:181} ERROR - nats: encountered error
Traceback (most recent call last):
  File "/usr/local/lib/python3.10/site-packages/nats/aio/client.py", line 1301, in _select_next_server
    await self._transport.connect(
  File "/usr/local/lib/python3.10/site-packages/nats/aio/transport.py", line 118, in connect
    r, w = await asyncio.wait_for(
  File "/usr/local/lib/python3.10/asyncio/tasks.py", line 445, in wait_for
    return fut.result()
  File "/usr/local/lib/python3.10/asyncio/streams.py", line 47, in open_connection
    transport, _ = await loop.create_connection(
  File "/usr/local/lib/python3.10/asyncio/base_events.py", line 1025, in create_connection
    infos = await self._ensure_resolved(
  File "/usr/local/lib/python3.10/asyncio/base_events.py", line 1404, in _ensure_resolved
    return await loop.getaddrinfo(host, port, family=family, type=type,
  File "/usr/local/lib/python3.10/asyncio/base_events.py", line 860, in getaddrinfo
    return await self.run_in_executor(
  File "/usr/local/lib/python3.10/concurrent/futures/thread.py", line 58, in run
    result = self.fn(*self.args, **self.kwargs)
  File "/usr/local/lib/python3.10/socket.py", line 955, in getaddrinfo
    for res in _socket.getaddrinfo(host, port, family, type, proto, flags):
socket.gaierror: [Errno -2] Name or service not known
[2022-10-05T09:24:28.011+0000] {client.py:181} ERROR - nats: encountered error
Traceback (most recent call last):
  File "/usr/local/lib/python3.10/site-packages/nats/aio/client.py", line 1301, in _select_next_server
    await self._transport.connect(
  File "/usr/local/lib/python3.10/site-packages/nats/aio/transport.py", line 118, in connect
    r, w = await asyncio.wait_for(
  File "/usr/local/lib/python3.10/asyncio/tasks.py", line 445, in wait_for
    return fut.result()
  File "/usr/local/lib/python3.10/asyncio/streams.py", line 47, in open_connection
    transport, _ = await loop.create_connection(
  File "/usr/local/lib/python3.10/asyncio/base_events.py", line 1025, in create_connection
    infos = await self._ensure_resolved(
  File "/usr/local/lib/python3.10/asyncio/base_events.py", line 1404, in _ensure_resolved
    return await loop.getaddrinfo(host, port, family=family, type=type,
  File "/usr/local/lib/python3.10/asyncio/base_events.py", line 860, in getaddrinfo
    return await self.run_in_executor(
  File "/usr/local/lib/python3.10/concurrent/futures/thread.py", line 58, in run
    result = self.fn(*self.args, **self.kwargs)
  File "/usr/local/lib/python3.10/socket.py", line 955, in getaddrinfo
    for res in _socket.getaddrinfo(host, port, family, type, proto, flags):
socket.gaierror: [Errno -2] Name or service not known
[2022-10-05T09:24:30.036+0000] {client.py:181} ERROR - nats: encountered error
Traceback (most recent call last):
  File "/usr/local/lib/python3.10/site-packages/nats/aio/client.py", line 1301, in _select_next_server
    await self._transport.connect(
  File "/usr/local/lib/python3.10/site-packages/nats/aio/transport.py", line 118, in connect
    r, w = await asyncio.wait_for(
  File "/usr/local/lib/python3.10/asyncio/tasks.py", line 445, in wait_for
    return fut.result()
  File "/usr/local/lib/python3.10/asyncio/streams.py", line 47, in open_connection
    transport, _ = await loop.create_connection(
  File "/usr/local/lib/python3.10/asyncio/base_events.py", line 1025, in create_connection
    infos = await self._ensure_resolved(
  File "/usr/local/lib/python3.10/asyncio/base_events.py", line 1404, in _ensure_resolved
    return await loop.getaddrinfo(host, port, family=family, type=type,
  File "/usr/local/lib/python3.10/asyncio/base_events.py", line 860, in getaddrinfo
    return await self.run_in_executor(
  File "/usr/local/lib/python3.10/concurrent/futures/thread.py", line 58, in run
    result = self.fn(*self.args, **self.kwargs)
  File "/usr/local/lib/python3.10/socket.py", line 955, in getaddrinfo
    for res in _socket.getaddrinfo(host, port, family, type, proto, flags):
socket.gaierror: [Errno -2] Name or service not known
[2022-10-05T09:24:32.059+0000] {client.py:181} ERROR - nats: encountered error
Traceback (most recent call last):
  File "/usr/local/lib/python3.10/site-packages/nats/aio/client.py", line 1301, in _select_next_server
    await self._transport.connect(
  File "/usr/local/lib/python3.10/site-packages/nats/aio/transport.py", line 118, in connect
    r, w = await asyncio.wait_for(
  File "/usr/local/lib/python3.10/asyncio/tasks.py", line 445, in wait_for
    return fut.result()
  File "/usr/local/lib/python3.10/asyncio/streams.py", line 47, in open_connection
    transport, _ = await loop.create_connection(
  File "/usr/local/lib/python3.10/asyncio/base_events.py", line 1025, in create_connection
    infos = await self._ensure_resolved(
  File "/usr/local/lib/python3.10/asyncio/base_events.py", line 1404, in _ensure_resolved
    return await loop.getaddrinfo(host, port, family=family, type=type,
  File "/usr/local/lib/python3.10/asyncio/base_events.py", line 860, in getaddrinfo
    return await self.run_in_executor(
  File "/usr/local/lib/python3.10/concurrent/futures/thread.py", line 58, in run
    result = self.fn(*self.args, **self.kwargs)
  File "/usr/local/lib/python3.10/socket.py", line 955, in getaddrinfo
    for res in _socket.getaddrinfo(host, port, family, type, proto, flags):
socket.gaierror: [Errno -2] Name or service not known
[2022-10-05T09:24:34.074+0000] {client.py:181} ERROR - nats: encountered error
Traceback (most recent call last):
  File "/usr/local/lib/python3.10/site-packages/nats/aio/client.py", line 1301, in _select_next_server
    await self._transport.connect(
  File "/usr/local/lib/python3.10/site-packages/nats/aio/transport.py", line 118, in connect
    r, w = await asyncio.wait_for(
  File "/usr/local/lib/python3.10/asyncio/tasks.py", line 445, in wait_for
    return fut.result()
  File "/usr/local/lib/python3.10/asyncio/streams.py", line 47, in open_connection
    transport, _ = await loop.create_connection(
  File "/usr/local/lib/python3.10/asyncio/base_events.py", line 1025, in create_connection
    infos = await self._ensure_resolved(
  File "/usr/local/lib/python3.10/asyncio/base_events.py", line 1404, in _ensure_resolved
    return await loop.getaddrinfo(host, port, family=family, type=type,
  File "/usr/local/lib/python3.10/asyncio/base_events.py", line 860, in getaddrinfo
    return await self.run_in_executor(
  File "/usr/local/lib/python3.10/concurrent/futures/thread.py", line 58, in run
    result = self.fn(*self.args, **self.kwargs)
  File "/usr/local/lib/python3.10/socket.py", line 955, in getaddrinfo
    for res in _socket.getaddrinfo(host, port, family, type, proto, flags):
socket.gaierror: [Errno -2] Name or service not known
[2022-10-05T09:24:36.090+0000] {client.py:181} ERROR - nats: encountered error
Traceback (most recent call last):
  File "/usr/local/lib/python3.10/site-packages/nats/aio/client.py", line 1301, in _select_next_server
    await self._transport.connect(
  File "/usr/local/lib/python3.10/site-packages/nats/aio/transport.py", line 118, in connect
    r, w = await asyncio.wait_for(
  File "/usr/local/lib/python3.10/asyncio/tasks.py", line 445, in wait_for
    return fut.result()
  File "/usr/local/lib/python3.10/asyncio/streams.py", line 47, in open_connection
    transport, _ = await loop.create_connection(
  File "/usr/local/lib/python3.10/asyncio/base_events.py", line 1025, in create_connection
    infos = await self._ensure_resolved(
  File "/usr/local/lib/python3.10/asyncio/base_events.py", line 1404, in _ensure_resolved
    return await loop.getaddrinfo(host, port, family=family, type=type,
  File "/usr/local/lib/python3.10/asyncio/base_events.py", line 860, in getaddrinfo
    return await self.run_in_executor(
  File "/usr/local/lib/python3.10/concurrent/futures/thread.py", line 58, in run
    result = self.fn(*self.args, **self.kwargs)
  File "/usr/local/lib/python3.10/socket.py", line 955, in getaddrinfo
    for res in _socket.getaddrinfo(host, port, family, type, proto, flags):
socket.gaierror: [Errno -2] Name or service not known
[2022-10-05T09:24:38.107+0000] {client.py:181} ERROR - nats: encountered error
Traceback (most recent call last):
  File "/usr/local/lib/python3.10/site-packages/nats/aio/client.py", line 1301, in _select_next_server
    await self._transport.connect(
  File "/usr/local/lib/python3.10/site-packages/nats/aio/transport.py", line 118, in connect
    r, w = await asyncio.wait_for(
  File "/usr/local/lib/python3.10/asyncio/tasks.py", line 445, in wait_for
    return fut.result()
  File "/usr/local/lib/python3.10/asyncio/streams.py", line 47, in open_connection
    transport, _ = await loop.create_connection(
  File "/usr/local/lib/python3.10/asyncio/base_events.py", line 1025, in create_connection
    infos = await self._ensure_resolved(
  File "/usr/local/lib/python3.10/asyncio/base_events.py", line 1404, in _ensure_resolved
    return await loop.getaddrinfo(host, port, family=family, type=type,
  File "/usr/local/lib/python3.10/asyncio/base_events.py", line 860, in getaddrinfo
    return await self.run_in_executor(
  File "/usr/local/lib/python3.10/concurrent/futures/thread.py", line 58, in run
    result = self.fn(*self.args, **self.kwargs)
  File "/usr/local/lib/python3.10/socket.py", line 955, in getaddrinfo
    for res in _socket.getaddrinfo(host, port, family, type, proto, flags):
socket.gaierror: [Errno -2] Name or service not known
[2022-10-05T09:24:40.130+0000] {client.py:181} ERROR - nats: encountered error
Traceback (most recent call last):
  File "/usr/local/lib/python3.10/site-packages/nats/aio/client.py", line 1301, in _select_next_server
    await self._transport.connect(
  File "/usr/local/lib/python3.10/site-packages/nats/aio/transport.py", line 118, in connect
    r, w = await asyncio.wait_for(
  File "/usr/local/lib/python3.10/asyncio/tasks.py", line 445, in wait_for
    return fut.result()
  File "/usr/local/lib/python3.10/asyncio/streams.py", line 47, in open_connection
    transport, _ = await loop.create_connection(
  File "/usr/local/lib/python3.10/asyncio/base_events.py", line 1025, in create_connection
    infos = await self._ensure_resolved(
  File "/usr/local/lib/python3.10/asyncio/base_events.py", line 1404, in _ensure_resolved
    return await loop.getaddrinfo(host, port, family=family, type=type,
  File "/usr/local/lib/python3.10/asyncio/base_events.py", line 860, in getaddrinfo
    return await self.run_in_executor(
  File "/usr/local/lib/python3.10/concurrent/futures/thread.py", line 58, in run
    result = self.fn(*self.args, **self.kwargs)
  File "/usr/local/lib/python3.10/socket.py", line 955, in getaddrinfo
    for res in _socket.getaddrinfo(host, port, family, type, proto, flags):
socket.gaierror: [Errno -2] Name or service not known
[2022-10-05T09:24:42.146+0000] {client.py:181} ERROR - nats: encountered error
Traceback (most recent call last):
  File "/usr/local/lib/python3.10/site-packages/nats/aio/client.py", line 1301, in _select_next_server
    await self._transport.connect(
  File "/usr/local/lib/python3.10/site-packages/nats/aio/transport.py", line 118, in connect
    r, w = await asyncio.wait_for(
  File "/usr/local/lib/python3.10/asyncio/tasks.py", line 445, in wait_for
    return fut.result()
  File "/usr/local/lib/python3.10/asyncio/streams.py", line 47, in open_connection
    transport, _ = await loop.create_connection(
  File "/usr/local/lib/python3.10/asyncio/base_events.py", line 1025, in create_connection
    infos = await self._ensure_resolved(
  File "/usr/local/lib/python3.10/asyncio/base_events.py", line 1404, in _ensure_resolved
    return await loop.getaddrinfo(host, port, family=family, type=type,
  File "/usr/local/lib/python3.10/asyncio/base_events.py", line 860, in getaddrinfo
    return await self.run_in_executor(
  File "/usr/local/lib/python3.10/concurrent/futures/thread.py", line 58, in run
    result = self.fn(*self.args, **self.kwargs)
  File "/usr/local/lib/python3.10/socket.py", line 955, in getaddrinfo
    for res in _socket.getaddrinfo(host, port, family, type, proto, flags):
socket.gaierror: [Errno -2] Name or service not known
[2022-10-05T09:24:44.157+0000] {client.py:181} ERROR - nats: encountered error
Traceback (most recent call last):
  File "/usr/local/lib/python3.10/site-packages/nats/aio/client.py", line 1301, in _select_next_server
    await self._transport.connect(
  File "/usr/local/lib/python3.10/site-packages/nats/aio/transport.py", line 118, in connect
    r, w = await asyncio.wait_for(
  File "/usr/local/lib/python3.10/asyncio/tasks.py", line 445, in wait_for
    return fut.result()
  File "/usr/local/lib/python3.10/asyncio/streams.py", line 47, in open_connection
    transport, _ = await loop.create_connection(
  File "/usr/local/lib/python3.10/asyncio/base_events.py", line 1025, in create_connection
    infos = await self._ensure_resolved(
  File "/usr/local/lib/python3.10/asyncio/base_events.py", line 1404, in _ensure_resolved
    return await loop.getaddrinfo(host, port, family=family, type=type,
  File "/usr/local/lib/python3.10/asyncio/base_events.py", line 860, in getaddrinfo
    return await self.run_in_executor(
  File "/usr/local/lib/python3.10/concurrent/futures/thread.py", line 58, in run
    result = self.fn(*self.args, **self.kwargs)
  File "/usr/local/lib/python3.10/socket.py", line 955, in getaddrinfo
    for res in _socket.getaddrinfo(host, port, family, type, proto, flags):
socket.gaierror: [Errno -2] Name or service not known
[2022-10-05T09:24:46.173+0000] {client.py:181} ERROR - nats: encountered error
Traceback (most recent call last):
  File "/usr/local/lib/python3.10/site-packages/nats/aio/client.py", line 1301, in _select_next_server
    await self._transport.connect(
  File "/usr/local/lib/python3.10/site-packages/nats/aio/transport.py", line 118, in connect
    r, w = await asyncio.wait_for(
  File "/usr/local/lib/python3.10/asyncio/tasks.py", line 445, in wait_for
    return fut.result()
  File "/usr/local/lib/python3.10/asyncio/streams.py", line 47, in open_connection
    transport, _ = await loop.create_connection(
  File "/usr/local/lib/python3.10/asyncio/base_events.py", line 1025, in create_connection
    infos = await self._ensure_resolved(
  File "/usr/local/lib/python3.10/asyncio/base_events.py", line 1404, in _ensure_resolved
    return await loop.getaddrinfo(host, port, family=family, type=type,
  File "/usr/local/lib/python3.10/asyncio/base_events.py", line 860, in getaddrinfo
    return await self.run_in_executor(
  File "/usr/local/lib/python3.10/concurrent/futures/thread.py", line 58, in run
    result = self.fn(*self.args, **self.kwargs)
  File "/usr/local/lib/python3.10/socket.py", line 955, in getaddrinfo
    for res in _socket.getaddrinfo(host, port, family, type, proto, flags):
socket.gaierror: [Errno -2] Name or service not known
[2022-10-05T09:24:48.182+0000] {client.py:181} ERROR - nats: encountered error
Traceback (most recent call last):
  File "/usr/local/lib/python3.10/site-packages/nats/aio/client.py", line 1301, in _select_next_server
    await self._transport.connect(
  File "/usr/local/lib/python3.10/site-packages/nats/aio/transport.py", line 118, in connect
    r, w = await asyncio.wait_for(
  File "/usr/local/lib/python3.10/asyncio/tasks.py", line 445, in wait_for
    return fut.result()
  File "/usr/local/lib/python3.10/asyncio/streams.py", line 47, in open_connection
    transport, _ = await loop.create_connection(
  File "/usr/local/lib/python3.10/asyncio/base_events.py", line 1025, in create_connection
    infos = await self._ensure_resolved(
  File "/usr/local/lib/python3.10/asyncio/base_events.py", line 1404, in _ensure_resolved
    return await loop.getaddrinfo(host, port, family=family, type=type,
  File "/usr/local/lib/python3.10/asyncio/base_events.py", line 860, in getaddrinfo
    return await self.run_in_executor(
  File "/usr/local/lib/python3.10/concurrent/futures/thread.py", line 58, in run
    result = self.fn(*self.args, **self.kwargs)
  File "/usr/local/lib/python3.10/socket.py", line 955, in getaddrinfo
    for res in _socket.getaddrinfo(host, port, family, type, proto, flags):
socket.gaierror: [Errno -2] Name or service not known
[2022-10-05T09:24:50.199+0000] {client.py:181} ERROR - nats: encountered error
Traceback (most recent call last):
  File "/usr/local/lib/python3.10/site-packages/nats/aio/client.py", line 1301, in _select_next_server
    await self._transport.connect(
  File "/usr/local/lib/python3.10/site-packages/nats/aio/transport.py", line 118, in connect
    r, w = await asyncio.wait_for(
  File "/usr/local/lib/python3.10/asyncio/tasks.py", line 445, in wait_for
    return fut.result()
  File "/usr/local/lib/python3.10/asyncio/streams.py", line 47, in open_connection
    transport, _ = await loop.create_connection(
  File "/usr/local/lib/python3.10/asyncio/base_events.py", line 1025, in create_connection
    infos = await self._ensure_resolved(
  File "/usr/local/lib/python3.10/asyncio/base_events.py", line 1404, in _ensure_resolved
    return await loop.getaddrinfo(host, port, family=family, type=type,
  File "/usr/local/lib/python3.10/asyncio/base_events.py", line 860, in getaddrinfo
    return await self.run_in_executor(
  File "/usr/local/lib/python3.10/concurrent/futures/thread.py", line 58, in run
    result = self.fn(*self.args, **self.kwargs)
  File "/usr/local/lib/python3.10/socket.py", line 955, in getaddrinfo
    for res in _socket.getaddrinfo(host, port, family, type, proto, flags):
socket.gaierror: [Errno -2] Name or service not known
[2022-10-05T09:24:52.225+0000] {client.py:181} ERROR - nats: encountered error
Traceback (most recent call last):
  File "/usr/local/lib/python3.10/site-packages/nats/aio/client.py", line 1301, in _select_next_server
    await self._transport.connect(
  File "/usr/local/lib/python3.10/site-packages/nats/aio/transport.py", line 118, in connect
    r, w = await asyncio.wait_for(
  File "/usr/local/lib/python3.10/asyncio/tasks.py", line 445, in wait_for
    return fut.result()
  File "/usr/local/lib/python3.10/asyncio/streams.py", line 47, in open_connection
    transport, _ = await loop.create_connection(
  File "/usr/local/lib/python3.10/asyncio/base_events.py", line 1025, in create_connection
    infos = await self._ensure_resolved(
  File "/usr/local/lib/python3.10/asyncio/base_events.py", line 1404, in _ensure_resolved
    return await loop.getaddrinfo(host, port, family=family, type=type,
  File "/usr/local/lib/python3.10/asyncio/base_events.py", line 860, in getaddrinfo
    return await self.run_in_executor(
  File "/usr/local/lib/python3.10/concurrent/futures/thread.py", line 58, in run
    result = self.fn(*self.args, **self.kwargs)
  File "/usr/local/lib/python3.10/socket.py", line 955, in getaddrinfo
    for res in _socket.getaddrinfo(host, port, family, type, proto, flags):
socket.gaierror: [Errno -2] Name or service not known
[2022-10-05T09:24:54.239+0000] {client.py:181} ERROR - nats: encountered error
Traceback (most recent call last):
  File "/usr/local/lib/python3.10/site-packages/nats/aio/client.py", line 1301, in _select_next_server
    await self._transport.connect(
  File "/usr/local/lib/python3.10/site-packages/nats/aio/transport.py", line 118, in connect
    r, w = await asyncio.wait_for(
  File "/usr/local/lib/python3.10/asyncio/tasks.py", line 445, in wait_for
    return fut.result()
  File "/usr/local/lib/python3.10/asyncio/streams.py", line 47, in open_connection
    transport, _ = await loop.create_connection(
  File "/usr/local/lib/python3.10/asyncio/base_events.py", line 1025, in create_connection
    infos = await self._ensure_resolved(
  File "/usr/local/lib/python3.10/asyncio/base_events.py", line 1404, in _ensure_resolved
    return await loop.getaddrinfo(host, port, family=family, type=type,
  File "/usr/local/lib/python3.10/asyncio/base_events.py", line 860, in getaddrinfo
    return await self.run_in_executor(
  File "/usr/local/lib/python3.10/concurrent/futures/thread.py", line 58, in run
    result = self.fn(*self.args, **self.kwargs)
  File "/usr/local/lib/python3.10/socket.py", line 955, in getaddrinfo
    for res in _socket.getaddrinfo(host, port, family, type, proto, flags):
socket.gaierror: [Errno -2] Name or service not known
[2022-10-05T09:24:56.248+0000] {client.py:181} ERROR - nats: encountered error
Traceback (most recent call last):
  File "/usr/local/lib/python3.10/site-packages/nats/aio/client.py", line 1301, in _select_next_server
    await self._transport.connect(
  File "/usr/local/lib/python3.10/site-packages/nats/aio/transport.py", line 118, in connect
    r, w = await asyncio.wait_for(
  File "/usr/local/lib/python3.10/asyncio/tasks.py", line 445, in wait_for
    return fut.result()
  File "/usr/local/lib/python3.10/asyncio/streams.py", line 47, in open_connection
    transport, _ = await loop.create_connection(
  File "/usr/local/lib/python3.10/asyncio/base_events.py", line 1025, in create_connection
    infos = await self._ensure_resolved(
  File "/usr/local/lib/python3.10/asyncio/base_events.py", line 1404, in _ensure_resolved
    return await loop.getaddrinfo(host, port, family=family, type=type,
  File "/usr/local/lib/python3.10/asyncio/base_events.py", line 860, in getaddrinfo
    return await self.run_in_executor(
  File "/usr/local/lib/python3.10/concurrent/futures/thread.py", line 58, in run
    result = self.fn(*self.args, **self.kwargs)
  File "/usr/local/lib/python3.10/socket.py", line 955, in getaddrinfo
    for res in _socket.getaddrinfo(host, port, family, type, proto, flags):
socket.gaierror: [Errno -2] Name or service not known
[2022-10-05T09:24:58.264+0000] {client.py:181} ERROR - nats: encountered error
Traceback (most recent call last):
  File "/usr/local/lib/python3.10/site-packages/nats/aio/client.py", line 1301, in _select_next_server
    await self._transport.connect(
  File "/usr/local/lib/python3.10/site-packages/nats/aio/transport.py", line 118, in connect
    r, w = await asyncio.wait_for(
  File "/usr/local/lib/python3.10/asyncio/tasks.py", line 445, in wait_for
    return fut.result()
  File "/usr/local/lib/python3.10/asyncio/streams.py", line 47, in open_connection
    transport, _ = await loop.create_connection(
  File "/usr/local/lib/python3.10/asyncio/base_events.py", line 1025, in create_connection
    infos = await self._ensure_resolved(
  File "/usr/local/lib/python3.10/asyncio/base_events.py", line 1404, in _ensure_resolved
    return await loop.getaddrinfo(host, port, family=family, type=type,
  File "/usr/local/lib/python3.10/asyncio/base_events.py", line 860, in getaddrinfo
    return await self.run_in_executor(
  File "/usr/local/lib/python3.10/concurrent/futures/thread.py", line 58, in run
    result = self.fn(*self.args, **self.kwargs)
  File "/usr/local/lib/python3.10/socket.py", line 955, in getaddrinfo
    for res in _socket.getaddrinfo(host, port, family, type, proto, flags):
socket.gaierror: [Errno -2] Name or service not known
[2022-10-05T09:25:00.294+0000] {client.py:181} ERROR - nats: encountered error
Traceback (most recent call last):
  File "/usr/local/lib/python3.10/site-packages/nats/aio/client.py", line 1301, in _select_next_server
    await self._transport.connect(
  File "/usr/local/lib/python3.10/site-packages/nats/aio/transport.py", line 118, in connect
    r, w = await asyncio.wait_for(
  File "/usr/local/lib/python3.10/asyncio/tasks.py", line 445, in wait_for
    return fut.result()
  File "/usr/local/lib/python3.10/asyncio/streams.py", line 47, in open_connection
    transport, _ = await loop.create_connection(
  File "/usr/local/lib/python3.10/asyncio/base_events.py", line 1025, in create_connection
    infos = await self._ensure_resolved(
  File "/usr/local/lib/python3.10/asyncio/base_events.py", line 1404, in _ensure_resolved
    return await loop.getaddrinfo(host, port, family=family, type=type,
  File "/usr/local/lib/python3.10/asyncio/base_events.py", line 860, in getaddrinfo
    return await self.run_in_executor(
  File "/usr/local/lib/python3.10/concurrent/futures/thread.py", line 58, in run
    result = self.fn(*self.args, **self.kwargs)
  File "/usr/local/lib/python3.10/socket.py", line 955, in getaddrinfo
    for res in _socket.getaddrinfo(host, port, family, type, proto, flags):
socket.gaierror: [Errno -2] Name or service not known
[2022-10-05T09:25:02.302+0000] {client.py:181} ERROR - nats: encountered error
Traceback (most recent call last):
  File "/usr/local/lib/python3.10/site-packages/nats/aio/client.py", line 1301, in _select_next_server
    await self._transport.connect(
  File "/usr/local/lib/python3.10/site-packages/nats/aio/transport.py", line 118, in connect
    r, w = await asyncio.wait_for(
  File "/usr/local/lib/python3.10/asyncio/tasks.py", line 445, in wait_for
    return fut.result()
  File "/usr/local/lib/python3.10/asyncio/streams.py", line 47, in open_connection
    transport, _ = await loop.create_connection(
  File "/usr/local/lib/python3.10/asyncio/base_events.py", line 1025, in create_connection
    infos = await self._ensure_resolved(
  File "/usr/local/lib/python3.10/asyncio/base_events.py", line 1404, in _ensure_resolved
    return await loop.getaddrinfo(host, port, family=family, type=type,
  File "/usr/local/lib/python3.10/asyncio/base_events.py", line 860, in getaddrinfo
    return await self.run_in_executor(
  File "/usr/local/lib/python3.10/concurrent/futures/thread.py", line 58, in run
    result = self.fn(*self.args, **self.kwargs)
  File "/usr/local/lib/python3.10/socket.py", line 955, in getaddrinfo
    for res in _socket.getaddrinfo(host, port, family, type, proto, flags):
socket.gaierror: [Errno -2] Name or service not known
[2022-10-05T09:25:04.314+0000] {client.py:181} ERROR - nats: encountered error
Traceback (most recent call last):
  File "/usr/local/lib/python3.10/site-packages/nats/aio/client.py", line 1301, in _select_next_server
    await self._transport.connect(
  File "/usr/local/lib/python3.10/site-packages/nats/aio/transport.py", line 118, in connect
    r, w = await asyncio.wait_for(
  File "/usr/local/lib/python3.10/asyncio/tasks.py", line 445, in wait_for
    return fut.result()
  File "/usr/local/lib/python3.10/asyncio/streams.py", line 47, in open_connection
    transport, _ = await loop.create_connection(
  File "/usr/local/lib/python3.10/asyncio/base_events.py", line 1025, in create_connection
    infos = await self._ensure_resolved(
  File "/usr/local/lib/python3.10/asyncio/base_events.py", line 1404, in _ensure_resolved
    return await loop.getaddrinfo(host, port, family=family, type=type,
  File "/usr/local/lib/python3.10/asyncio/base_events.py", line 860, in getaddrinfo
    return await self.run_in_executor(
  File "/usr/local/lib/python3.10/concurrent/futures/thread.py", line 58, in run
    result = self.fn(*self.args, **self.kwargs)
  File "/usr/local/lib/python3.10/socket.py", line 955, in getaddrinfo
    for res in _socket.getaddrinfo(host, port, family, type, proto, flags):
socket.gaierror: [Errno -2] Name or service not known
[2022-10-05T09:25:06.334+0000] {client.py:181} ERROR - nats: encountered error
Traceback (most recent call last):
  File "/usr/local/lib/python3.10/site-packages/nats/aio/client.py", line 1301, in _select_next_server
    await self._transport.connect(
  File "/usr/local/lib/python3.10/site-packages/nats/aio/transport.py", line 118, in connect
    r, w = await asyncio.wait_for(
  File "/usr/local/lib/python3.10/asyncio/tasks.py", line 445, in wait_for
    return fut.result()
  File "/usr/local/lib/python3.10/asyncio/streams.py", line 47, in open_connection
    transport, _ = await loop.create_connection(
  File "/usr/local/lib/python3.10/asyncio/base_events.py", line 1025, in create_connection
    infos = await self._ensure_resolved(
  File "/usr/local/lib/python3.10/asyncio/base_events.py", line 1404, in _ensure_resolved
    return await loop.getaddrinfo(host, port, family=family, type=type,
  File "/usr/local/lib/python3.10/asyncio/base_events.py", line 860, in getaddrinfo
    return await self.run_in_executor(
  File "/usr/local/lib/python3.10/concurrent/futures/thread.py", line 58, in run
    result = self.fn(*self.args, **self.kwargs)
  File "/usr/local/lib/python3.10/socket.py", line 955, in getaddrinfo
    for res in _socket.getaddrinfo(host, port, family, type, proto, flags):
socket.gaierror: [Errno -2] Name or service not known
[2022-10-05T09:25:08.354+0000] {client.py:181} ERROR - nats: encountered error
Traceback (most recent call last):
  File "/usr/local/lib/python3.10/site-packages/nats/aio/client.py", line 1301, in _select_next_server
    await self._transport.connect(
  File "/usr/local/lib/python3.10/site-packages/nats/aio/transport.py", line 118, in connect
    r, w = await asyncio.wait_for(
  File "/usr/local/lib/python3.10/asyncio/tasks.py", line 445, in wait_for
    return fut.result()
  File "/usr/local/lib/python3.10/asyncio/streams.py", line 47, in open_connection
    transport, _ = await loop.create_connection(
  File "/usr/local/lib/python3.10/asyncio/base_events.py", line 1025, in create_connection
    infos = await self._ensure_resolved(
  File "/usr/local/lib/python3.10/asyncio/base_events.py", line 1404, in _ensure_resolved
    return await loop.getaddrinfo(host, port, family=family, type=type,
  File "/usr/local/lib/python3.10/asyncio/base_events.py", line 860, in getaddrinfo
    return await self.run_in_executor(
  File "/usr/local/lib/python3.10/concurrent/futures/thread.py", line 58, in run
    result = self.fn(*self.args, **self.kwargs)
  File "/usr/local/lib/python3.10/socket.py", line 955, in getaddrinfo
    for res in _socket.getaddrinfo(host, port, family, type, proto, flags):
socket.gaierror: [Errno -2] Name or service not known
[2022-10-05T09:25:10.380+0000] {client.py:181} ERROR - nats: encountered error
Traceback (most recent call last):
  File "/usr/local/lib/python3.10/site-packages/nats/aio/client.py", line 1301, in _select_next_server
    await self._transport.connect(
  File "/usr/local/lib/python3.10/site-packages/nats/aio/transport.py", line 118, in connect
    r, w = await asyncio.wait_for(
  File "/usr/local/lib/python3.10/asyncio/tasks.py", line 445, in wait_for
    return fut.result()
  File "/usr/local/lib/python3.10/asyncio/streams.py", line 47, in open_connection
    transport, _ = await loop.create_connection(
  File "/usr/local/lib/python3.10/asyncio/base_events.py", line 1025, in create_connection
    infos = await self._ensure_resolved(
  File "/usr/local/lib/python3.10/asyncio/base_events.py", line 1404, in _ensure_resolved
    return await loop.getaddrinfo(host, port, family=family, type=type,
  File "/usr/local/lib/python3.10/asyncio/base_events.py", line 860, in getaddrinfo
    return await self.run_in_executor(
  File "/usr/local/lib/python3.10/concurrent/futures/thread.py", line 58, in run
    result = self.fn(*self.args, **self.kwargs)
  File "/usr/local/lib/python3.10/socket.py", line 955, in getaddrinfo
    for res in _socket.getaddrinfo(host, port, family, type, proto, flags):
socket.gaierror: [Errno -2] Name or service not known
[2022-10-05T09:25:12.393+0000] {client.py:181} ERROR - nats: encountered error
Traceback (most recent call last):
  File "/usr/local/lib/python3.10/site-packages/nats/aio/client.py", line 1301, in _select_next_server
    await self._transport.connect(
  File "/usr/local/lib/python3.10/site-packages/nats/aio/transport.py", line 118, in connect
    r, w = await asyncio.wait_for(
  File "/usr/local/lib/python3.10/asyncio/tasks.py", line 445, in wait_for
    return fut.result()
  File "/usr/local/lib/python3.10/asyncio/streams.py", line 47, in open_connection
    transport, _ = await loop.create_connection(
  File "/usr/local/lib/python3.10/asyncio/base_events.py", line 1025, in create_connection
    infos = await self._ensure_resolved(
  File "/usr/local/lib/python3.10/asyncio/base_events.py", line 1404, in _ensure_resolved
    return await loop.getaddrinfo(host, port, family=family, type=type,
  File "/usr/local/lib/python3.10/asyncio/base_events.py", line 860, in getaddrinfo
    return await self.run_in_executor(
  File "/usr/local/lib/python3.10/concurrent/futures/thread.py", line 58, in run
    result = self.fn(*self.args, **self.kwargs)
  File "/usr/local/lib/python3.10/socket.py", line 955, in getaddrinfo
    for res in _socket.getaddrinfo(host, port, family, type, proto, flags):
socket.gaierror: [Errno -2] Name or service not known
[2022-10-05T09:25:14.420+0000] {client.py:181} ERROR - nats: encountered error
Traceback (most recent call last):
  File "/usr/local/lib/python3.10/site-packages/nats/aio/client.py", line 1301, in _select_next_server
    await self._transport.connect(
  File "/usr/local/lib/python3.10/site-packages/nats/aio/transport.py", line 118, in connect
    r, w = await asyncio.wait_for(
  File "/usr/local/lib/python3.10/asyncio/tasks.py", line 445, in wait_for
    return fut.result()
  File "/usr/local/lib/python3.10/asyncio/streams.py", line 47, in open_connection
    transport, _ = await loop.create_connection(
  File "/usr/local/lib/python3.10/asyncio/base_events.py", line 1025, in create_connection
    infos = await self._ensure_resolved(
  File "/usr/local/lib/python3.10/asyncio/base_events.py", line 1404, in _ensure_resolved
    return await loop.getaddrinfo(host, port, family=family, type=type,
  File "/usr/local/lib/python3.10/asyncio/base_events.py", line 860, in getaddrinfo
    return await self.run_in_executor(
  File "/usr/local/lib/python3.10/concurrent/futures/thread.py", line 58, in run
    result = self.fn(*self.args, **self.kwargs)
  File "/usr/local/lib/python3.10/socket.py", line 955, in getaddrinfo
    for res in _socket.getaddrinfo(host, port, family, type, proto, flags):
socket.gaierror: [Errno -2] Name or service not known
[2022-10-05T09:25:16.429+0000] {client.py:181} ERROR - nats: encountered error
Traceback (most recent call last):
  File "/usr/local/lib/python3.10/site-packages/nats/aio/client.py", line 1301, in _select_next_server
    await self._transport.connect(
  File "/usr/local/lib/python3.10/site-packages/nats/aio/transport.py", line 118, in connect
    r, w = await asyncio.wait_for(
  File "/usr/local/lib/python3.10/asyncio/tasks.py", line 445, in wait_for
    return fut.result()
  File "/usr/local/lib/python3.10/asyncio/streams.py", line 47, in open_connection
    transport, _ = await loop.create_connection(
  File "/usr/local/lib/python3.10/asyncio/base_events.py", line 1025, in create_connection
    infos = await self._ensure_resolved(
  File "/usr/local/lib/python3.10/asyncio/base_events.py", line 1404, in _ensure_resolved
    return await loop.getaddrinfo(host, port, family=family, type=type,
  File "/usr/local/lib/python3.10/asyncio/base_events.py", line 860, in getaddrinfo
    return await self.run_in_executor(
  File "/usr/local/lib/python3.10/concurrent/futures/thread.py", line 58, in run
    result = self.fn(*self.args, **self.kwargs)
  File "/usr/local/lib/python3.10/socket.py", line 955, in getaddrinfo
    for res in _socket.getaddrinfo(host, port, family, type, proto, flags):
socket.gaierror: [Errno -2] Name or service not known
[2022-10-05T09:25:18.442+0000] {client.py:181} ERROR - nats: encountered error
Traceback (most recent call last):
  File "/usr/local/lib/python3.10/site-packages/nats/aio/client.py", line 1301, in _select_next_server
    await self._transport.connect(
  File "/usr/local/lib/python3.10/site-packages/nats/aio/transport.py", line 118, in connect
    r, w = await asyncio.wait_for(
  File "/usr/local/lib/python3.10/asyncio/tasks.py", line 445, in wait_for
    return fut.result()
  File "/usr/local/lib/python3.10/asyncio/streams.py", line 47, in open_connection
    transport, _ = await loop.create_connection(
  File "/usr/local/lib/python3.10/asyncio/base_events.py", line 1025, in create_connection
    infos = await self._ensure_resolved(
  File "/usr/local/lib/python3.10/asyncio/base_events.py", line 1404, in _ensure_resolved
    return await loop.getaddrinfo(host, port, family=family, type=type,
  File "/usr/local/lib/python3.10/asyncio/base_events.py", line 860, in getaddrinfo
    return await self.run_in_executor(
  File "/usr/local/lib/python3.10/concurrent/futures/thread.py", line 58, in run
    result = self.fn(*self.args, **self.kwargs)
  File "/usr/local/lib/python3.10/socket.py", line 955, in getaddrinfo
    for res in _socket.getaddrinfo(host, port, family, type, proto, flags):
socket.gaierror: [Errno -2] Name or service not known
[2022-10-05T09:25:20.457+0000] {client.py:181} ERROR - nats: encountered error
Traceback (most recent call last):
  File "/usr/local/lib/python3.10/site-packages/nats/aio/client.py", line 1301, in _select_next_server
    await self._transport.connect(
  File "/usr/local/lib/python3.10/site-packages/nats/aio/transport.py", line 118, in connect
    r, w = await asyncio.wait_for(
  File "/usr/local/lib/python3.10/asyncio/tasks.py", line 445, in wait_for
    return fut.result()
  File "/usr/local/lib/python3.10/asyncio/streams.py", line 47, in open_connection
    transport, _ = await loop.create_connection(
  File "/usr/local/lib/python3.10/asyncio/base_events.py", line 1025, in create_connection
    infos = await self._ensure_resolved(
  File "/usr/local/lib/python3.10/asyncio/base_events.py", line 1404, in _ensure_resolved
    return await loop.getaddrinfo(host, port, family=family, type=type,
  File "/usr/local/lib/python3.10/asyncio/base_events.py", line 860, in getaddrinfo
    return await self.run_in_executor(
  File "/usr/local/lib/python3.10/concurrent/futures/thread.py", line 58, in run
    result = self.fn(*self.args, **self.kwargs)
  File "/usr/local/lib/python3.10/socket.py", line 955, in getaddrinfo
    for res in _socket.getaddrinfo(host, port, family, type, proto, flags):
socket.gaierror: [Errno -2] Name or service not known
[2022-10-05T09:25:22.486+0000] {client.py:181} ERROR - nats: encountered error
Traceback (most recent call last):
  File "/usr/local/lib/python3.10/site-packages/nats/aio/client.py", line 1301, in _select_next_server
    await self._transport.connect(
  File "/usr/local/lib/python3.10/site-packages/nats/aio/transport.py", line 118, in connect
    r, w = await asyncio.wait_for(
  File "/usr/local/lib/python3.10/asyncio/tasks.py", line 445, in wait_for
    return fut.result()
  File "/usr/local/lib/python3.10/asyncio/streams.py", line 47, in open_connection
    transport, _ = await loop.create_connection(
  File "/usr/local/lib/python3.10/asyncio/base_events.py", line 1025, in create_connection
    infos = await self._ensure_resolved(
  File "/usr/local/lib/python3.10/asyncio/base_events.py", line 1404, in _ensure_resolved
    return await loop.getaddrinfo(host, port, family=family, type=type,
  File "/usr/local/lib/python3.10/asyncio/base_events.py", line 860, in getaddrinfo
    return await self.run_in_executor(
  File "/usr/local/lib/python3.10/concurrent/futures/thread.py", line 58, in run
    result = self.fn(*self.args, **self.kwargs)
  File "/usr/local/lib/python3.10/socket.py", line 955, in getaddrinfo
    for res in _socket.getaddrinfo(host, port, family, type, proto, flags):
socket.gaierror: [Errno -2] Name or service not known
[2022-10-05T09:25:24.504+0000] {client.py:181} ERROR - nats: encountered error
Traceback (most recent call last):
  File "/usr/local/lib/python3.10/site-packages/nats/aio/client.py", line 1301, in _select_next_server
    await self._transport.connect(
  File "/usr/local/lib/python3.10/site-packages/nats/aio/transport.py", line 118, in connect
    r, w = await asyncio.wait_for(
  File "/usr/local/lib/python3.10/asyncio/tasks.py", line 445, in wait_for
    return fut.result()
  File "/usr/local/lib/python3.10/asyncio/streams.py", line 47, in open_connection
    transport, _ = await loop.create_connection(
  File "/usr/local/lib/python3.10/asyncio/base_events.py", line 1025, in create_connection
    infos = await self._ensure_resolved(
  File "/usr/local/lib/python3.10/asyncio/base_events.py", line 1404, in _ensure_resolved
    return await loop.getaddrinfo(host, port, family=family, type=type,
  File "/usr/local/lib/python3.10/asyncio/base_events.py", line 860, in getaddrinfo
    return await self.run_in_executor(
  File "/usr/local/lib/python3.10/concurrent/futures/thread.py", line 58, in run
    result = self.fn(*self.args, **self.kwargs)
  File "/usr/local/lib/python3.10/socket.py", line 955, in getaddrinfo
    for res in _socket.getaddrinfo(host, port, family, type, proto, flags):
socket.gaierror: [Errno -2] Name or service not known
[2022-10-05T09:25:26.513+0000] {client.py:181} ERROR - nats: encountered error
Traceback (most recent call last):
  File "/usr/local/lib/python3.10/site-packages/nats/aio/client.py", line 1301, in _select_next_server
    await self._transport.connect(
  File "/usr/local/lib/python3.10/site-packages/nats/aio/transport.py", line 118, in connect
    r, w = await asyncio.wait_for(
  File "/usr/local/lib/python3.10/asyncio/tasks.py", line 445, in wait_for
    return fut.result()
  File "/usr/local/lib/python3.10/asyncio/streams.py", line 47, in open_connection
    transport, _ = await loop.create_connection(
  File "/usr/local/lib/python3.10/asyncio/base_events.py", line 1025, in create_connection
    infos = await self._ensure_resolved(
  File "/usr/local/lib/python3.10/asyncio/base_events.py", line 1404, in _ensure_resolved
    return await loop.getaddrinfo(host, port, family=family, type=type,
  File "/usr/local/lib/python3.10/asyncio/base_events.py", line 860, in getaddrinfo
    return await self.run_in_executor(
  File "/usr/local/lib/python3.10/concurrent/futures/thread.py", line 58, in run
    result = self.fn(*self.args, **self.kwargs)
  File "/usr/local/lib/python3.10/socket.py", line 955, in getaddrinfo
    for res in _socket.getaddrinfo(host, port, family, type, proto, flags):
socket.gaierror: [Errno -2] Name or service not known
[2022-10-05T09:25:28.523+0000] {client.py:181} ERROR - nats: encountered error
Traceback (most recent call last):
  File "/usr/local/lib/python3.10/site-packages/nats/aio/client.py", line 1301, in _select_next_server
    await self._transport.connect(
  File "/usr/local/lib/python3.10/site-packages/nats/aio/transport.py", line 118, in connect
    r, w = await asyncio.wait_for(
  File "/usr/local/lib/python3.10/asyncio/tasks.py", line 445, in wait_for
    return fut.result()
  File "/usr/local/lib/python3.10/asyncio/streams.py", line 47, in open_connection
    transport, _ = await loop.create_connection(
  File "/usr/local/lib/python3.10/asyncio/base_events.py", line 1025, in create_connection
    infos = await self._ensure_resolved(
  File "/usr/local/lib/python3.10/asyncio/base_events.py", line 1404, in _ensure_resolved
    return await loop.getaddrinfo(host, port, family=family, type=type,
  File "/usr/local/lib/python3.10/asyncio/base_events.py", line 860, in getaddrinfo
    return await self.run_in_executor(
  File "/usr/local/lib/python3.10/concurrent/futures/thread.py", line 58, in run
    result = self.fn(*self.args, **self.kwargs)
  File "/usr/local/lib/python3.10/socket.py", line 955, in getaddrinfo
    for res in _socket.getaddrinfo(host, port, family, type, proto, flags):
socket.gaierror: [Errno -2] Name or service not known
[2022-10-05T09:25:30.540+0000] {client.py:181} ERROR - nats: encountered error
Traceback (most recent call last):
  File "/usr/local/lib/python3.10/site-packages/nats/aio/client.py", line 1301, in _select_next_server
    await self._transport.connect(
  File "/usr/local/lib/python3.10/site-packages/nats/aio/transport.py", line 118, in connect
    r, w = await asyncio.wait_for(
  File "/usr/local/lib/python3.10/asyncio/tasks.py", line 445, in wait_for
    return fut.result()
  File "/usr/local/lib/python3.10/asyncio/streams.py", line 47, in open_connection
    transport, _ = await loop.create_connection(
  File "/usr/local/lib/python3.10/asyncio/base_events.py", line 1025, in create_connection
    infos = await self._ensure_resolved(
  File "/usr/local/lib/python3.10/asyncio/base_events.py", line 1404, in _ensure_resolved
    return await loop.getaddrinfo(host, port, family=family, type=type,
  File "/usr/local/lib/python3.10/asyncio/base_events.py", line 860, in getaddrinfo
    return await self.run_in_executor(
  File "/usr/local/lib/python3.10/concurrent/futures/thread.py", line 58, in run
    result = self.fn(*self.args, **self.kwargs)
  File "/usr/local/lib/python3.10/socket.py", line 955, in getaddrinfo
    for res in _socket.getaddrinfo(host, port, family, type, proto, flags):
socket.gaierror: [Errno -2] Name or service not known
[2022-10-05T09:25:32.551+0000] {client.py:181} ERROR - nats: encountered error
Traceback (most recent call last):
  File "/usr/local/lib/python3.10/site-packages/nats/aio/client.py", line 1301, in _select_next_server
    await self._transport.connect(
  File "/usr/local/lib/python3.10/site-packages/nats/aio/transport.py", line 118, in connect
    r, w = await asyncio.wait_for(
  File "/usr/local/lib/python3.10/asyncio/tasks.py", line 445, in wait_for
    return fut.result()
  File "/usr/local/lib/python3.10/asyncio/streams.py", line 47, in open_connection
    transport, _ = await loop.create_connection(
  File "/usr/local/lib/python3.10/asyncio/base_events.py", line 1025, in create_connection
    infos = await self._ensure_resolved(
  File "/usr/local/lib/python3.10/asyncio/base_events.py", line 1404, in _ensure_resolved
    return await loop.getaddrinfo(host, port, family=family, type=type,
  File "/usr/local/lib/python3.10/asyncio/base_events.py", line 860, in getaddrinfo
    return await self.run_in_executor(
  File "/usr/local/lib/python3.10/concurrent/futures/thread.py", line 58, in run
    result = self.fn(*self.args, **self.kwargs)
  File "/usr/local/lib/python3.10/socket.py", line 955, in getaddrinfo
    for res in _socket.getaddrinfo(host, port, family, type, proto, flags):
socket.gaierror: [Errno -2] Name or service not known
[2022-10-05T09:25:34.582+0000] {client.py:181} ERROR - nats: encountered error
Traceback (most recent call last):
  File "/usr/local/lib/python3.10/site-packages/nats/aio/client.py", line 1301, in _select_next_server
    await self._transport.connect(
  File "/usr/local/lib/python3.10/site-packages/nats/aio/transport.py", line 118, in connect
    r, w = await asyncio.wait_for(
  File "/usr/local/lib/python3.10/asyncio/tasks.py", line 445, in wait_for
    return fut.result()
  File "/usr/local/lib/python3.10/asyncio/streams.py", line 47, in open_connection
    transport, _ = await loop.create_connection(
  File "/usr/local/lib/python3.10/asyncio/base_events.py", line 1025, in create_connection
    infos = await self._ensure_resolved(
  File "/usr/local/lib/python3.10/asyncio/base_events.py", line 1404, in _ensure_resolved
    return await loop.getaddrinfo(host, port, family=family, type=type,
  File "/usr/local/lib/python3.10/asyncio/base_events.py", line 860, in getaddrinfo
    return await self.run_in_executor(
  File "/usr/local/lib/python3.10/concurrent/futures/thread.py", line 58, in run
    result = self.fn(*self.args, **self.kwargs)
  File "/usr/local/lib/python3.10/socket.py", line 955, in getaddrinfo
    for res in _socket.getaddrinfo(host, port, family, type, proto, flags):
socket.gaierror: [Errno -2] Name or service not known
[2022-10-05T09:25:36.595+0000] {client.py:181} ERROR - nats: encountered error
Traceback (most recent call last):
  File "/usr/local/lib/python3.10/site-packages/nats/aio/client.py", line 1301, in _select_next_server
    await self._transport.connect(
  File "/usr/local/lib/python3.10/site-packages/nats/aio/transport.py", line 118, in connect
    r, w = await asyncio.wait_for(
  File "/usr/local/lib/python3.10/asyncio/tasks.py", line 445, in wait_for
    return fut.result()
  File "/usr/local/lib/python3.10/asyncio/streams.py", line 47, in open_connection
    transport, _ = await loop.create_connection(
  File "/usr/local/lib/python3.10/asyncio/base_events.py", line 1025, in create_connection
    infos = await self._ensure_resolved(
  File "/usr/local/lib/python3.10/asyncio/base_events.py", line 1404, in _ensure_resolved
    return await loop.getaddrinfo(host, port, family=family, type=type,
  File "/usr/local/lib/python3.10/asyncio/base_events.py", line 860, in getaddrinfo
    return await self.run_in_executor(
  File "/usr/local/lib/python3.10/concurrent/futures/thread.py", line 58, in run
    result = self.fn(*self.args, **self.kwargs)
  File "/usr/local/lib/python3.10/socket.py", line 955, in getaddrinfo
    for res in _socket.getaddrinfo(host, port, family, type, proto, flags):
socket.gaierror: [Errno -2] Name or service not known
[2022-10-05T09:25:38.609+0000] {client.py:181} ERROR - nats: encountered error
Traceback (most recent call last):
  File "/usr/local/lib/python3.10/site-packages/nats/aio/client.py", line 1301, in _select_next_server
    await self._transport.connect(
  File "/usr/local/lib/python3.10/site-packages/nats/aio/transport.py", line 118, in connect
    r, w = await asyncio.wait_for(
  File "/usr/local/lib/python3.10/asyncio/tasks.py", line 445, in wait_for
    return fut.result()
  File "/usr/local/lib/python3.10/asyncio/streams.py", line 47, in open_connection
    transport, _ = await loop.create_connection(
  File "/usr/local/lib/python3.10/asyncio/base_events.py", line 1025, in create_connection
    infos = await self._ensure_resolved(
  File "/usr/local/lib/python3.10/asyncio/base_events.py", line 1404, in _ensure_resolved
    return await loop.getaddrinfo(host, port, family=family, type=type,
  File "/usr/local/lib/python3.10/asyncio/base_events.py", line 860, in getaddrinfo
    return await self.run_in_executor(
  File "/usr/local/lib/python3.10/concurrent/futures/thread.py", line 58, in run
    result = self.fn(*self.args, **self.kwargs)
  File "/usr/local/lib/python3.10/socket.py", line 955, in getaddrinfo
    for res in _socket.getaddrinfo(host, port, family, type, proto, flags):
socket.gaierror: [Errno -2] Name or service not known
[2022-10-05T09:25:40.627+0000] {client.py:181} ERROR - nats: encountered error
Traceback (most recent call last):
  File "/usr/local/lib/python3.10/site-packages/nats/aio/client.py", line 1301, in _select_next_server
    await self._transport.connect(
  File "/usr/local/lib/python3.10/site-packages/nats/aio/transport.py", line 118, in connect
    r, w = await asyncio.wait_for(
  File "/usr/local/lib/python3.10/asyncio/tasks.py", line 445, in wait_for
    return fut.result()
  File "/usr/local/lib/python3.10/asyncio/streams.py", line 47, in open_connection
    transport, _ = await loop.create_connection(
  File "/usr/local/lib/python3.10/asyncio/base_events.py", line 1025, in create_connection
    infos = await self._ensure_resolved(
  File "/usr/local/lib/python3.10/asyncio/base_events.py", line 1404, in _ensure_resolved
    return await loop.getaddrinfo(host, port, family=family, type=type,
  File "/usr/local/lib/python3.10/asyncio/base_events.py", line 860, in getaddrinfo
    return await self.run_in_executor(
  File "/usr/local/lib/python3.10/concurrent/futures/thread.py", line 58, in run
    result = self.fn(*self.args, **self.kwargs)
  File "/usr/local/lib/python3.10/socket.py", line 955, in getaddrinfo
    for res in _socket.getaddrinfo(host, port, family, type, proto, flags):
socket.gaierror: [Errno -2] Name or service not known
[2022-10-05T09:25:42.637+0000] {client.py:181} ERROR - nats: encountered error
Traceback (most recent call last):
  File "/usr/local/lib/python3.10/site-packages/nats/aio/client.py", line 1301, in _select_next_server
    await self._transport.connect(
  File "/usr/local/lib/python3.10/site-packages/nats/aio/transport.py", line 118, in connect
    r, w = await asyncio.wait_for(
  File "/usr/local/lib/python3.10/asyncio/tasks.py", line 445, in wait_for
    return fut.result()
  File "/usr/local/lib/python3.10/asyncio/streams.py", line 47, in open_connection
    transport, _ = await loop.create_connection(
  File "/usr/local/lib/python3.10/asyncio/base_events.py", line 1025, in create_connection
    infos = await self._ensure_resolved(
  File "/usr/local/lib/python3.10/asyncio/base_events.py", line 1404, in _ensure_resolved
    return await loop.getaddrinfo(host, port, family=family, type=type,
  File "/usr/local/lib/python3.10/asyncio/base_events.py", line 860, in getaddrinfo
    return await self.run_in_executor(
  File "/usr/local/lib/python3.10/concurrent/futures/thread.py", line 58, in run
    result = self.fn(*self.args, **self.kwargs)
  File "/usr/local/lib/python3.10/socket.py", line 955, in getaddrinfo
    for res in _socket.getaddrinfo(host, port, family, type, proto, flags):
socket.gaierror: [Errno -2] Name or service not known
[2022-10-05T09:25:44.656+0000] {client.py:181} ERROR - nats: encountered error
Traceback (most recent call last):
  File "/usr/local/lib/python3.10/site-packages/nats/aio/client.py", line 1301, in _select_next_server
    await self._transport.connect(
  File "/usr/local/lib/python3.10/site-packages/nats/aio/transport.py", line 118, in connect
    r, w = await asyncio.wait_for(
  File "/usr/local/lib/python3.10/asyncio/tasks.py", line 445, in wait_for
    return fut.result()
  File "/usr/local/lib/python3.10/asyncio/streams.py", line 47, in open_connection
    transport, _ = await loop.create_connection(
  File "/usr/local/lib/python3.10/asyncio/base_events.py", line 1025, in create_connection
    infos = await self._ensure_resolved(
  File "/usr/local/lib/python3.10/asyncio/base_events.py", line 1404, in _ensure_resolved
    return await loop.getaddrinfo(host, port, family=family, type=type,
  File "/usr/local/lib/python3.10/asyncio/base_events.py", line 860, in getaddrinfo
    return await self.run_in_executor(
  File "/usr/local/lib/python3.10/concurrent/futures/thread.py", line 58, in run
    result = self.fn(*self.args, **self.kwargs)
  File "/usr/local/lib/python3.10/socket.py", line 955, in getaddrinfo
    for res in _socket.getaddrinfo(host, port, family, type, proto, flags):
socket.gaierror: [Errno -2] Name or service not known
[2022-10-05T09:25:46.665+0000] {client.py:181} ERROR - nats: encountered error
Traceback (most recent call last):
  File "/usr/local/lib/python3.10/site-packages/nats/aio/client.py", line 1301, in _select_next_server
    await self._transport.connect(
  File "/usr/local/lib/python3.10/site-packages/nats/aio/transport.py", line 118, in connect
    r, w = await asyncio.wait_for(
  File "/usr/local/lib/python3.10/asyncio/tasks.py", line 445, in wait_for
    return fut.result()
  File "/usr/local/lib/python3.10/asyncio/streams.py", line 47, in open_connection
    transport, _ = await loop.create_connection(
  File "/usr/local/lib/python3.10/asyncio/base_events.py", line 1025, in create_connection
    infos = await self._ensure_resolved(
  File "/usr/local/lib/python3.10/asyncio/base_events.py", line 1404, in _ensure_resolved
    return await loop.getaddrinfo(host, port, family=family, type=type,
  File "/usr/local/lib/python3.10/asyncio/base_events.py", line 860, in getaddrinfo
    return await self.run_in_executor(
  File "/usr/local/lib/python3.10/concurrent/futures/thread.py", line 58, in run
    result = self.fn(*self.args, **self.kwargs)
  File "/usr/local/lib/python3.10/socket.py", line 955, in getaddrinfo
    for res in _socket.getaddrinfo(host, port, family, type, proto, flags):
socket.gaierror: [Errno -2] Name or service not known
[2022-10-05T09:25:48.679+0000] {client.py:181} ERROR - nats: encountered error
Traceback (most recent call last):
  File "/usr/local/lib/python3.10/site-packages/nats/aio/client.py", line 1301, in _select_next_server
    await self._transport.connect(
  File "/usr/local/lib/python3.10/site-packages/nats/aio/transport.py", line 118, in connect
    r, w = await asyncio.wait_for(
  File "/usr/local/lib/python3.10/asyncio/tasks.py", line 445, in wait_for
    return fut.result()
  File "/usr/local/lib/python3.10/asyncio/streams.py", line 47, in open_connection
    transport, _ = await loop.create_connection(
  File "/usr/local/lib/python3.10/asyncio/base_events.py", line 1025, in create_connection
    infos = await self._ensure_resolved(
  File "/usr/local/lib/python3.10/asyncio/base_events.py", line 1404, in _ensure_resolved
    return await loop.getaddrinfo(host, port, family=family, type=type,
  File "/usr/local/lib/python3.10/asyncio/base_events.py", line 860, in getaddrinfo
    return await self.run_in_executor(
  File "/usr/local/lib/python3.10/concurrent/futures/thread.py", line 58, in run
    result = self.fn(*self.args, **self.kwargs)
  File "/usr/local/lib/python3.10/socket.py", line 955, in getaddrinfo
    for res in _socket.getaddrinfo(host, port, family, type, proto, flags):
socket.gaierror: [Errno -2] Name or service not known
[2022-10-05T09:25:50.692+0000] {client.py:181} ERROR - nats: encountered error
Traceback (most recent call last):
  File "/usr/local/lib/python3.10/site-packages/nats/aio/client.py", line 1301, in _select_next_server
    await self._transport.connect(
  File "/usr/local/lib/python3.10/site-packages/nats/aio/transport.py", line 118, in connect
    r, w = await asyncio.wait_for(
  File "/usr/local/lib/python3.10/asyncio/tasks.py", line 445, in wait_for
    return fut.result()
  File "/usr/local/lib/python3.10/asyncio/streams.py", line 47, in open_connection
    transport, _ = await loop.create_connection(
  File "/usr/local/lib/python3.10/asyncio/base_events.py", line 1025, in create_connection
    infos = await self._ensure_resolved(
  File "/usr/local/lib/python3.10/asyncio/base_events.py", line 1404, in _ensure_resolved
    return await loop.getaddrinfo(host, port, family=family, type=type,
  File "/usr/local/lib/python3.10/asyncio/base_events.py", line 860, in getaddrinfo
    return await self.run_in_executor(
  File "/usr/local/lib/python3.10/concurrent/futures/thread.py", line 58, in run
    result = self.fn(*self.args, **self.kwargs)
  File "/usr/local/lib/python3.10/socket.py", line 955, in getaddrinfo
    for res in _socket.getaddrinfo(host, port, family, type, proto, flags):
socket.gaierror: [Errno -2] Name or service not known
[2022-10-05T09:25:52.709+0000] {client.py:181} ERROR - nats: encountered error
Traceback (most recent call last):
  File "/usr/local/lib/python3.10/site-packages/nats/aio/client.py", line 1301, in _select_next_server
    await self._transport.connect(
  File "/usr/local/lib/python3.10/site-packages/nats/aio/transport.py", line 118, in connect
    r, w = await asyncio.wait_for(
  File "/usr/local/lib/python3.10/asyncio/tasks.py", line 445, in wait_for
    return fut.result()
  File "/usr/local/lib/python3.10/asyncio/streams.py", line 47, in open_connection
    transport, _ = await loop.create_connection(
  File "/usr/local/lib/python3.10/asyncio/base_events.py", line 1025, in create_connection
    infos = await self._ensure_resolved(
  File "/usr/local/lib/python3.10/asyncio/base_events.py", line 1404, in _ensure_resolved
    return await loop.getaddrinfo(host, port, family=family, type=type,
  File "/usr/local/lib/python3.10/asyncio/base_events.py", line 860, in getaddrinfo
    return await self.run_in_executor(
  File "/usr/local/lib/python3.10/concurrent/futures/thread.py", line 58, in run
    result = self.fn(*self.args, **self.kwargs)
  File "/usr/local/lib/python3.10/socket.py", line 955, in getaddrinfo
    for res in _socket.getaddrinfo(host, port, family, type, proto, flags):
socket.gaierror: [Errno -2] Name or service not known
[2022-10-05T09:25:54.731+0000] {client.py:181} ERROR - nats: encountered error
Traceback (most recent call last):
  File "/usr/local/lib/python3.10/site-packages/nats/aio/client.py", line 1301, in _select_next_server
    await self._transport.connect(
  File "/usr/local/lib/python3.10/site-packages/nats/aio/transport.py", line 118, in connect
    r, w = await asyncio.wait_for(
  File "/usr/local/lib/python3.10/asyncio/tasks.py", line 445, in wait_for
    return fut.result()
  File "/usr/local/lib/python3.10/asyncio/streams.py", line 47, in open_connection
    transport, _ = await loop.create_connection(
  File "/usr/local/lib/python3.10/asyncio/base_events.py", line 1025, in create_connection
    infos = await self._ensure_resolved(
  File "/usr/local/lib/python3.10/asyncio/base_events.py", line 1404, in _ensure_resolved
    return await loop.getaddrinfo(host, port, family=family, type=type,
  File "/usr/local/lib/python3.10/asyncio/base_events.py", line 860, in getaddrinfo
    return await self.run_in_executor(
  File "/usr/local/lib/python3.10/concurrent/futures/thread.py", line 58, in run
    result = self.fn(*self.args, **self.kwargs)
  File "/usr/local/lib/python3.10/socket.py", line 955, in getaddrinfo
    for res in _socket.getaddrinfo(host, port, family, type, proto, flags):
socket.gaierror: [Errno -2] Name or service not known
[2022-10-05T09:25:56.742+0000] {client.py:181} ERROR - nats: encountered error
Traceback (most recent call last):
  File "/usr/local/lib/python3.10/site-packages/nats/aio/client.py", line 1301, in _select_next_server
    await self._transport.connect(
  File "/usr/local/lib/python3.10/site-packages/nats/aio/transport.py", line 118, in connect
    r, w = await asyncio.wait_for(
  File "/usr/local/lib/python3.10/asyncio/tasks.py", line 445, in wait_for
    return fut.result()
  File "/usr/local/lib/python3.10/asyncio/streams.py", line 47, in open_connection
    transport, _ = await loop.create_connection(
  File "/usr/local/lib/python3.10/asyncio/base_events.py", line 1025, in create_connection
    infos = await self._ensure_resolved(
  File "/usr/local/lib/python3.10/asyncio/base_events.py", line 1404, in _ensure_resolved
    return await loop.getaddrinfo(host, port, family=family, type=type,
  File "/usr/local/lib/python3.10/asyncio/base_events.py", line 860, in getaddrinfo
    return await self.run_in_executor(
  File "/usr/local/lib/python3.10/concurrent/futures/thread.py", line 58, in run
    result = self.fn(*self.args, **self.kwargs)
  File "/usr/local/lib/python3.10/socket.py", line 955, in getaddrinfo
    for res in _socket.getaddrinfo(host, port, family, type, proto, flags):
socket.gaierror: [Errno -2] Name or service not known
[2022-10-05T09:25:58.760+0000] {client.py:181} ERROR - nats: encountered error
Traceback (most recent call last):
  File "/usr/local/lib/python3.10/site-packages/nats/aio/client.py", line 1301, in _select_next_server
    await self._transport.connect(
  File "/usr/local/lib/python3.10/site-packages/nats/aio/transport.py", line 118, in connect
    r, w = await asyncio.wait_for(
  File "/usr/local/lib/python3.10/asyncio/tasks.py", line 445, in wait_for
    return fut.result()
  File "/usr/local/lib/python3.10/asyncio/streams.py", line 47, in open_connection
    transport, _ = await loop.create_connection(
  File "/usr/local/lib/python3.10/asyncio/base_events.py", line 1025, in create_connection
    infos = await self._ensure_resolved(
  File "/usr/local/lib/python3.10/asyncio/base_events.py", line 1404, in _ensure_resolved
    return await loop.getaddrinfo(host, port, family=family, type=type,
  File "/usr/local/lib/python3.10/asyncio/base_events.py", line 860, in getaddrinfo
    return await self.run_in_executor(
  File "/usr/local/lib/python3.10/concurrent/futures/thread.py", line 58, in run
    result = self.fn(*self.args, **self.kwargs)
  File "/usr/local/lib/python3.10/socket.py", line 955, in getaddrinfo
    for res in _socket.getaddrinfo(host, port, family, type, proto, flags):
socket.gaierror: [Errno -2] Name or service not known
[2022-10-05T09:26:00.773+0000] {client.py:181} ERROR - nats: encountered error
Traceback (most recent call last):
  File "/usr/local/lib/python3.10/site-packages/nats/aio/client.py", line 1301, in _select_next_server
    await self._transport.connect(
  File "/usr/local/lib/python3.10/site-packages/nats/aio/transport.py", line 118, in connect
    r, w = await asyncio.wait_for(
  File "/usr/local/lib/python3.10/asyncio/tasks.py", line 445, in wait_for
    return fut.result()
  File "/usr/local/lib/python3.10/asyncio/streams.py", line 47, in open_connection
    transport, _ = await loop.create_connection(
  File "/usr/local/lib/python3.10/asyncio/base_events.py", line 1025, in create_connection
    infos = await self._ensure_resolved(
  File "/usr/local/lib/python3.10/asyncio/base_events.py", line 1404, in _ensure_resolved
    return await loop.getaddrinfo(host, port, family=family, type=type,
  File "/usr/local/lib/python3.10/asyncio/base_events.py", line 860, in getaddrinfo
    return await self.run_in_executor(
  File "/usr/local/lib/python3.10/concurrent/futures/thread.py", line 58, in run
    result = self.fn(*self.args, **self.kwargs)
  File "/usr/local/lib/python3.10/socket.py", line 955, in getaddrinfo
    for res in _socket.getaddrinfo(host, port, family, type, proto, flags):
socket.gaierror: [Errno -2] Name or service not known
[2022-10-05T09:26:02.784+0000] {client.py:181} ERROR - nats: encountered error
Traceback (most recent call last):
  File "/usr/local/lib/python3.10/site-packages/nats/aio/client.py", line 1301, in _select_next_server
    await self._transport.connect(
  File "/usr/local/lib/python3.10/site-packages/nats/aio/transport.py", line 118, in connect
    r, w = await asyncio.wait_for(
  File "/usr/local/lib/python3.10/asyncio/tasks.py", line 445, in wait_for
    return fut.result()
  File "/usr/local/lib/python3.10/asyncio/streams.py", line 47, in open_connection
    transport, _ = await loop.create_connection(
  File "/usr/local/lib/python3.10/asyncio/base_events.py", line 1025, in create_connection
    infos = await self._ensure_resolved(
  File "/usr/local/lib/python3.10/asyncio/base_events.py", line 1404, in _ensure_resolved
    return await loop.getaddrinfo(host, port, family=family, type=type,
  File "/usr/local/lib/python3.10/asyncio/base_events.py", line 860, in getaddrinfo
    return await self.run_in_executor(
  File "/usr/local/lib/python3.10/concurrent/futures/thread.py", line 58, in run
    result = self.fn(*self.args, **self.kwargs)
  File "/usr/local/lib/python3.10/socket.py", line 955, in getaddrinfo
    for res in _socket.getaddrinfo(host, port, family, type, proto, flags):
socket.gaierror: [Errno -2] Name or service not known
[2022-10-05T09:26:04.801+0000] {client.py:181} ERROR - nats: encountered error
Traceback (most recent call last):
  File "/usr/local/lib/python3.10/site-packages/nats/aio/client.py", line 1301, in _select_next_server
    await self._transport.connect(
  File "/usr/local/lib/python3.10/site-packages/nats/aio/transport.py", line 118, in connect
    r, w = await asyncio.wait_for(
  File "/usr/local/lib/python3.10/asyncio/tasks.py", line 445, in wait_for
    return fut.result()
  File "/usr/local/lib/python3.10/asyncio/streams.py", line 47, in open_connection
    transport, _ = await loop.create_connection(
  File "/usr/local/lib/python3.10/asyncio/base_events.py", line 1025, in create_connection
    infos = await self._ensure_resolved(
  File "/usr/local/lib/python3.10/asyncio/base_events.py", line 1404, in _ensure_resolved
    return await loop.getaddrinfo(host, port, family=family, type=type,
  File "/usr/local/lib/python3.10/asyncio/base_events.py", line 860, in getaddrinfo
    return await self.run_in_executor(
  File "/usr/local/lib/python3.10/concurrent/futures/thread.py", line 58, in run
    result = self.fn(*self.args, **self.kwargs)
  File "/usr/local/lib/python3.10/socket.py", line 955, in getaddrinfo
    for res in _socket.getaddrinfo(host, port, family, type, proto, flags):
socket.gaierror: [Errno -2] Name or service not known
[2022-10-05T09:26:06.818+0000] {client.py:181} ERROR - nats: encountered error
Traceback (most recent call last):
  File "/usr/local/lib/python3.10/site-packages/nats/aio/client.py", line 1301, in _select_next_server
    await self._transport.connect(
  File "/usr/local/lib/python3.10/site-packages/nats/aio/transport.py", line 118, in connect
    r, w = await asyncio.wait_for(
  File "/usr/local/lib/python3.10/asyncio/tasks.py", line 445, in wait_for
    return fut.result()
  File "/usr/local/lib/python3.10/asyncio/streams.py", line 47, in open_connection
    transport, _ = await loop.create_connection(
  File "/usr/local/lib/python3.10/asyncio/base_events.py", line 1025, in create_connection
    infos = await self._ensure_resolved(
  File "/usr/local/lib/python3.10/asyncio/base_events.py", line 1404, in _ensure_resolved
    return await loop.getaddrinfo(host, port, family=family, type=type,
  File "/usr/local/lib/python3.10/asyncio/base_events.py", line 860, in getaddrinfo
    return await self.run_in_executor(
  File "/usr/local/lib/python3.10/concurrent/futures/thread.py", line 58, in run
    result = self.fn(*self.args, **self.kwargs)
  File "/usr/local/lib/python3.10/socket.py", line 955, in getaddrinfo
    for res in _socket.getaddrinfo(host, port, family, type, proto, flags):
socket.gaierror: [Errno -2] Name or service not known
[2022-10-05T09:26:08.833+0000] {client.py:181} ERROR - nats: encountered error
Traceback (most recent call last):
  File "/usr/local/lib/python3.10/site-packages/nats/aio/client.py", line 1301, in _select_next_server
    await self._transport.connect(
  File "/usr/local/lib/python3.10/site-packages/nats/aio/transport.py", line 118, in connect
    r, w = await asyncio.wait_for(
  File "/usr/local/lib/python3.10/asyncio/tasks.py", line 445, in wait_for
    return fut.result()
  File "/usr/local/lib/python3.10/asyncio/streams.py", line 47, in open_connection
    transport, _ = await loop.create_connection(
  File "/usr/local/lib/python3.10/asyncio/base_events.py", line 1025, in create_connection
    infos = await self._ensure_resolved(
  File "/usr/local/lib/python3.10/asyncio/base_events.py", line 1404, in _ensure_resolved
    return await loop.getaddrinfo(host, port, family=family, type=type,
  File "/usr/local/lib/python3.10/asyncio/base_events.py", line 860, in getaddrinfo
    return await self.run_in_executor(
  File "/usr/local/lib/python3.10/concurrent/futures/thread.py", line 58, in run
    result = self.fn(*self.args, **self.kwargs)
  File "/usr/local/lib/python3.10/socket.py", line 955, in getaddrinfo
    for res in _socket.getaddrinfo(host, port, family, type, proto, flags):
socket.gaierror: [Errno -2] Name or service not known
[2022-10-05T09:26:10.844+0000] {client.py:181} ERROR - nats: encountered error
Traceback (most recent call last):
  File "/usr/local/lib/python3.10/site-packages/nats/aio/client.py", line 1301, in _select_next_server
    await self._transport.connect(
  File "/usr/local/lib/python3.10/site-packages/nats/aio/transport.py", line 118, in connect
    r, w = await asyncio.wait_for(
  File "/usr/local/lib/python3.10/asyncio/tasks.py", line 445, in wait_for
    return fut.result()
  File "/usr/local/lib/python3.10/asyncio/streams.py", line 47, in open_connection
    transport, _ = await loop.create_connection(
  File "/usr/local/lib/python3.10/asyncio/base_events.py", line 1025, in create_connection
    infos = await self._ensure_resolved(
  File "/usr/local/lib/python3.10/asyncio/base_events.py", line 1404, in _ensure_resolved
    return await loop.getaddrinfo(host, port, family=family, type=type,
  File "/usr/local/lib/python3.10/asyncio/base_events.py", line 860, in getaddrinfo
    return await self.run_in_executor(
  File "/usr/local/lib/python3.10/concurrent/futures/thread.py", line 58, in run
    result = self.fn(*self.args, **self.kwargs)
  File "/usr/local/lib/python3.10/socket.py", line 955, in getaddrinfo
    for res in _socket.getaddrinfo(host, port, family, type, proto, flags):
socket.gaierror: [Errno -2] Name or service not known
[2022-10-05T09:26:10.845+0000] {taskinstance.py:1851} ERROR - Task failed with exception
Traceback (most recent call last):
  File "/usr/local/lib/python3.10/site-packages/airflow/decorators/base.py", line 188, in execute
    return_value = super().execute(context)
  File "/usr/local/lib/python3.10/site-packages/airflow/operators/python.py", line 175, in execute
    return_value = self.execute_callable()
  File "/usr/local/lib/python3.10/site-packages/airflow/operators/python.py", line 193, in execute_callable
    return self.python_callable(*self.op_args, **self.op_kwargs)
  File "/workspaces/pipeline-environment/test_airflow/dags/pipeline.py", line 54, in collect_messages
    asyncio.run(get_messages(start_time, end_time))
  File "/usr/local/lib/python3.10/asyncio/runners.py", line 44, in run
    return loop.run_until_complete(main)
  File "/usr/local/lib/python3.10/asyncio/base_events.py", line 646, in run_until_complete
    return future.result()
  File "/workspaces/pipeline-environment/test_airflow/dags/pipeline.py", line 78, in get_messages
    nc = await nats.connect("sandbox-toys-nats.sandbox.svc.cluster.local:4222")
  File "/usr/local/lib/python3.10/site-packages/nats/__init__.py", line 44, in connect
    await nc.connect(servers, **options)
  File "/usr/local/lib/python3.10/site-packages/nats/aio/client.py", line 478, in connect
    raise e
  File "/usr/local/lib/python3.10/site-packages/nats/aio/client.py", line 468, in connect
    await self._select_next_server()
  File "/usr/local/lib/python3.10/site-packages/nats/aio/client.py", line 1268, in _select_next_server
    raise errors.NoServersError
nats.errors.NoServersError: nats: no servers available for connection
[2022-10-05T09:26:10.849+0000] {taskinstance.py:1401} INFO - Marking task as FAILED. dag_id=dump_to_s3, task_id=collect_messages, execution_date=20221005T092405, start_date=20221005T092409, end_date=20221005T092610
[2022-10-05T09:26:10.884+0000] {standard_task_runner.py:102} ERROR - Failed to execute job 42 for task collect_messages (nats: no servers available for connection; 31725)
[2022-10-05T09:26:10.925+0000] {local_task_job.py:164} INFO - Task exited with return code 1
[2022-10-05T09:26:10.969+0000] {local_task_job.py:273} INFO - 0 downstream tasks scheduled from follow-on schedule check
