[32m2022-12-23 15:11:23 +0000[0m - dagster - [34mDEBUG[0m - generate_trajectories - 0e1d6487-2062-4336-acd9-4c8ff185b8eb - 7951 - LOGS_CAPTURED - Started capturing logs in process (pid: 7951).
[32m2022-12-23 15:11:23 +0000[0m - dagster - [34mDEBUG[0m - generate_trajectories - 0e1d6487-2062-4336-acd9-4c8ff185b8eb - 7951 - collect_data - STEP_START - Started execution of step "collect_data".
[32m2022-12-23 15:11:23 +0000[0m - dagster - [34mDEBUG[0m - generate_trajectories - 0e1d6487-2062-4336-acd9-4c8ff185b8eb - collect_data - Loading file from: /workspaces/pipeline-environment/dagster_pipelines/storage/0e1d6487-2062-4336-acd9-4c8ff185b8eb/get_interval/result
[32m2022-12-23 15:11:23 +0000[0m - dagster - [34mDEBUG[0m - generate_trajectories - 0e1d6487-2062-4336-acd9-4c8ff185b8eb - 7951 - collect_data - LOADED_INPUT - Loaded input "interval" using input manager "io_manager", from output "result" of step "get_interval"
[32m2022-12-23 15:11:23 +0000[0m - dagster - [34mDEBUG[0m - generate_trajectories - 0e1d6487-2062-4336-acd9-4c8ff185b8eb - 7951 - collect_data - STEP_INPUT - Got input "interval" of type "Tuple[datetime,datetime]". (Type check passed).
[32m2022-12-23 15:11:23 +0000[0m - dagster - [34mERROR[0m - [31mgenerate_trajectories - 0e1d6487-2062-4336-acd9-4c8ff185b8eb - 7951 - collect_data - STEP_FAILURE - Execution of step "collect_data" failed.

dagster._core.errors.DagsterExecutionStepExecutionError: Error occurred while executing op "collect_data"::

nats.js.errors.Error: nats: JetStream.Error consumer is already bound to a subscription

Stack Trace:
  File "/usr/local/lib/python3.10/site-packages/dagster/_core/execution/plan/utils.py", line 56, in op_execution_error_boundary
    yield
  File "/usr/local/lib/python3.10/site-packages/dagster/_utils/__init__.py", line 458, in iterate_with_context
    next_output = next(iterator)
  File "/usr/local/lib/python3.10/site-packages/dagster/_core/execution/plan/compute.py", line 112, in gen_from_async_gen
    yield loop.run_until_complete(async_gen.__anext__())
  File "/usr/local/lib/python3.10/asyncio/base_events.py", line 649, in run_until_complete
    return future.result()
  File "/usr/local/lib/python3.10/site-packages/dagster/_core/execution/plan/compute_generator.py", line 69, in _coerce_async_solid_to_async_gen
    result = await awaitable
  File "/workspaces/pipeline-environment/dagster_pipelines/dagster_pipelines/ops/trajectory_ops.py", line 22, in collect_data
    psub = await js.subscribe("ais", durable="fff")
  File "/usr/local/lib/python3.10/site-packages/nats/js/client.py", line 244, in subscribe
    raise nats.js.errors.Error(
[0m
